File: m3_learning/papers/2023_RHEED_PLD_SrTiO3/Data/XRD/treated_213nm-RSM_103.xrdml
<?xml version="1.0" encoding="utf-8"?>
<xrdMeasurements xmlns="http://www.xrdml.com/XRDMeasurement/2.2" xmlns:xsi="http://www.w3.org/2001/XMLSchema-instance" xsi:schemaLocation="http://www.xrdml.com/XRDMeasurement/2.2 http://www.xrdml.com/XRDMeasurement/2.2/XRDMeasurement.xsd" status="Completed">
	<comment>
		<entry>Configuration=3-axes Cradle_Reflection, Owner=User, Creation date=9/2/2021 3:55:24 PM</entry>
		<entry>Goniometer=Theta/Theta; Minimum step size 2Theta:0.0001; Minimum step size Omega:0.0001</entry>
		<entry>Sample stage=Chi-Phi-z stage 240 mm (reflection); Minimum step size Phi:0.01; Minimum step size Chi:0.01; Minimum step size Z:0.001</entry>
		<entry>Diffractometer system=EMPYREAN</entry>
		<entry>Measurement program=C:\PANalytical\Data Collector\Programs\Liyan Wu\Film programs\RSM slow 1.5 degree.xrdmp, Identifier={0A137119-D990-4D5D-A198-A9BB75A0EC1A}</entry>
	</comment>
	<sample type="To be analyzed">
		<id/>
		<name/>
		<preparedBy/>
	</sample>
	<xrdMeasurement status="Completed" measurementType="Area measurement" measurementStepAxis="Omega-2Theta" sampleMode="Reflection">
		<comment>
			<entry>PHD Lower Level = 4.02 (keV), PHD Upper Level = 11.26 (keV)</entry>
		</comment>
		<usedWavelength intended="K-Alpha">
			<kAlpha1 unit="Angstrom">1.5405980</kAlpha1>
			<kAlpha2 unit="Angstrom">1.5444260</kAlpha2>
			<kBeta unit="Angstrom">1.3922500</kBeta>
			<ratioKAlpha2KAlpha1>0</ratioKAlpha2KAlpha1>
		</usedWavelength>
		<incidentBeamPath>
			<radius unit="mm">240.00</radius>
			<xRayTube id="1010048" name="Empyrean Cu LFF HR (9430 033 7310x) DK432574">
				<tension unit="kV">45.0</tension>
				<current unit="mA">40.0</current>
				<anodeMaterial>Cu</anodeMaterial>
				<focus type="Line">
					<length unit="mm">12.0</length>
					<width unit="mm">0.4</width>
					<takeOffAngle unit="deg">4.4</takeOffAngle>
				</focus>
			</xRayTube>
			<xRayMirror xsi:type="xRayMirrorType" id="27080001" name="Inc. Beam Cu W/Si (hybrid MPD)" hybrid="true">
				<crystal type="Graded" shape="Parabolic">W/Si</crystal>
				<acceptanceAngle unit="deg">0.800</acceptanceAngle>
				<length unit="mm">55.3</length>
			</xRayMirror>
			<monochromator xsi:type="monochromatorType" id="23090002" name="Hybrid monochr. 2xGe220 Cu asym." hybrid="true">
				<crystal type="Asymmetric" shape="Flat">Ge</crystal>
				<numberOfReflections>2</numberOfReflections>
				<hkl>
					<h>2</h>
					<k>2</k>
					<l>0</l>
				</hkl>
			</monochromator>
			<divergenceSlit xsi:type="fixedDivergenceSlitType" id="22010005" name="Fixed slit 1/4°">
				<distanceToSample unit="mm">179.30</distanceToSample>
				<height unit="mm">0.38</height>
			</divergenceSlit>
		</incidentBeamPath>
		<diffractedBeamPath>
			<radius unit="mm">240.00</radius>
			<antiScatterSlit xsi:type="fixedAntiScatterSlitType" id="22060009" name="Programmable anti-scatter slit">
				<angle unit="deg">4</angle>
			</antiScatterSlit>
			<detector xsi:type="areaDetectorType" id="7010020" name="PIXcel3D-Medipix3 1x1 detector">
				<phd unit="%">
					<lowerLevel>25</lowerLevel>
					<upperLevel>70</upperLevel>
				</phd>
				<mode>Scanning snapshot equatorial</mode>
				<activeChannelsEquatorial>255</activeChannelsEquatorial>
				<activeChannelsAxial>255</activeChannelsAxial>
				<pitchEquatorial unit="mm">0.05500</pitchEquatorial>
				<pitchAxial unit="mm">0.05500</pitchAxial>
				<readOutPeriod unit="seconds">0.980</readOutPeriod>
			</detector>
		</diffractedBeamPath>
		<scan status="Completed" appendNumber="0" scanAxis="2Theta" mode="Continuous">
			<header>
				<startTimeStamp>2023-05-09T17:41:52-04:00</startTimeStamp>
				<endTimeStamp>2023-05-09T17:56:58-04:00</endTimeStamp>
				<author>
					<name>User</name>
				</author>
				<source>
					<applicationSoftware version="7.1">Data Collector</applicationSoftware>
					<instrumentControlSoftware version="8.2  20201204">EMPYREAN</instrumentControlSoftware>
					<instrumentID>0000000011260721</instrumentID>
				</source>
			</header>
			<dataPoints>
				<positions axis="2Theta" unit="deg">
					<startPosition>74.0070063943918</startPosition>
					<endPosition>77.3542761656082</endPosition>
				</positions>
				<positions axis="Omega" unit="deg">
					<commonPosition>19.42502064</commonPosition>
				</positions>
				<positions axis="Phi" unit="deg">
					<commonPosition>-92.99</commonPosition>
				</positions>
				<positions axis="Chi" unit="deg">
					<commonPosition>0</commonPosition>
				</positions>
				<positions axis="Z" unit="mm">
					<commonPosition>8.384</commonPosition>
				</positions>
				<commonCountingTime unit="seconds">0.974</commonCountingTime>
				<counts unit="counts">0 0 0 0 2 0 0 0 0 0 1 1 0 0 1 0 0 0 1 0 0 1 0 0 0 0 0 0 0 0 1 0 0 1 0 0 0 1 0 1 0 0 0 0 0 0 0 0 1 1 0 0 1 1 1 0 0 0 0 1 0 0 0 0 0 2 0 1 1 1 1 0 1 1 1 0 0 0 1 0 0 0 0 0 0 0 1 0 0 1 2 0 0 0 0 0 0 0 0 0 0 0 0 0 0 0 0 0 0 0 0 0 1 0 0 1 0 0 1 0 0 0 0 1 0 1 0 0 1 0 1 0 1 1 1 0 0 0 1 0 1 1 2 1 0 0 0 0 0 0 0 0 0 2 1 0 0 0 0 1 0 0 1 1 0 1 1 0 0 1 0 1 0 0 0 2 0 1 0 0 0 1 1 1 2 0 0 0 0 0 0 1 0 0 0 0 2 0 0 0 0 1 0 0 1 0 0 0 0 1 0 0 0 1 1 2 0 1 0 0 0 1 0 2 2 2 0 0 0 0 1 1 0 0 0 0 0 1 0 0 0 1 0 0 2 0 0 1 1 0 0 1 1 1 1</counts>
			</dataPoints>
		</scan>
		<scan status="Completed" appendNumber="0" scanAxis="2Theta" mode="Continuous">
			<header>
				<startTimeStamp>2023-05-09T17:41:52-04:00</startTimeStamp>
				<endTimeStamp>2023-05-09T17:56:58-04:00</endTimeStamp>
				<author>
					<name>User</name>
				</author>
				<source>
					<applicationSoftware version="7.1">Data Collector</applicationSoftware>
					<instrumentControlSoftware version="8.2  20201204">EMPYREAN</instrumentControlSoftware>
					<instrumentID>0000000011260721</instrumentID>
				</source>
			</header>
			<dataPoints>
				<positions axis="2Theta" unit="deg">
					<startPosition>74.0102889650716</startPosition>
					<endPosition>77.3575587362881</endPosition>
				</positions>
				<positions axis="Omega" unit="deg">
					<commonPosition>19.4266619253399</commonPosition>
				</positions>
				<positions axis="Phi" unit="deg">
					<commonPosition>-92.99</commonPosition>
				</positions>
				<positions axis="Chi" unit="deg">
					<commonPosition>0</commonPosition>
				</positions>
				<positions axis="Z" unit="mm">
					<commonPosition>8.384</commonPosition>
				</positions>
				<commonCountingTime unit="seconds">0.974</commonCountingTime>
				<counts unit="counts">0 0 0 1 0 1 0 0 0 0 0 0 0 0 0 1 0 0 0 0 0 0 0 0 1 3 0 0 0 0 0 1 0 1 0 0 0 0 1 0 0 1 0 1 0 0 0 0 0 0 1 1 0 0 1 0 0 1 0 0 0 1 0 0 0 0 0 0 0 0 0 1 1 0 0 0 0 0 0 0 0 1 1 0 1 0 0 0 0 0 2 0 0 0 0 0 0 0 0 0 0 0 0 0 0 0 1 0 0 2 1 0 0 0 0 0 0 0 0 1 0 1 0 1 0 1 1 0 0 0 0 0 0 0 0 0 0 0 0 0 0 0 1 0 0 1 0 0 0 0 0 2 0 0 0 0 0 0 2 0 0 0 1 2 0 0 0 0 0 0 1 1 0 0 1 0 0 0 0 1 0 0 0 0 0 0 0 0 0 1 1 0 0 1 1 1 1 0 0 0 1 0 0 0 2 0 2 0 0 3 1 1 0 0 1 1 0 0 1 1 0 0 0 0 0 2 1 2 0 0 0 0 0 1 0 1 0 0 0 3 0 1 3 0 0 0 0 0 0 1 0 0 1 0 0</counts>
			</dataPoints>
		</scan>
		<scan status="Completed" appendNumber="0" scanAxis="2Theta" mode="Continuous">
			<header>
				<startTimeStamp>2023-05-09T17:41:52-04:00</startTimeStamp>
				<endTimeStamp>2023-05-09T17:56:58-04:00</endTimeStamp>
				<author>
					<name>User</name>
				</author>
				<source>
					<applicationSoftware version="7.1">Data Collector</applicationSoftware>
					<instrumentControlSoftware version="8.2  20201204">EMPYREAN</instrumentControlSoftware>
					<instrumentID>0000000011260721</instrumentID>
				</source>
			</header>
			<dataPoints>
				<positions axis="2Theta" unit="deg">
					<startPosition>74.0135715357514</startPosition>
					<endPosition>77.3608413069679</endPosition>
				</positions>
				<positions axis="Omega" unit="deg">
					<commonPosition>19.4283032106798</commonPosition>
				</positions>
				<positions axis="Phi" unit="deg">
					<commonPosition>-92.99</commonPosition>
				</positions>
				<positions axis="Chi" unit="deg">
					<commonPosition>0</commonPosition>
				</positions>
				<positions axis="Z" unit="mm">
					<commonPosition>8.384</commonPosition>
				</positions>
				<commonCountingTime unit="seconds">0.974</commonCountingTime>
				<counts unit="counts">0 1 0 0 0 0 0 1 2 0 0 1 1 0 0 1 0 0 0 0 2 0 0 0 0 0 0 0 2 0 0 0 1 1 0 1 0 0 0 0 0 0 0 2 1 0 1 0 0 1 1 0 0 0 0 1 1 1 0 1 0 0 0 1 0 1 0 0 0 0 0 0 0 0 0 0 1 0 1 0 0 0 0 0 0 0 0 0 0 0 0 1 0 0 0 0 0 2 1 0 0 0 0 1 1 0 0 0 0 0 1 0 0 0 0 0 0 1 2 0 0 0 0 0 0 0 0 1 1 0 0 0 0 1 0 0 0 1 0 0 0 0 0 0 0 1 0 1 0 0 0 0 0 0 0 0 1 0 0 0 0 1 1 0 1 0 1 1 0 0 0 0 0 0 0 0 0 1 0 0 1 0 0 0 0 1 0 1 0 0 1 1 0 0 2 1 1 1 1 0 0 0 0 0 0 0 0 1 1 1 0 1 0 1 0 0 0 0 0 1 2 1 1 0 0 1 0 0 0 0 2 1 0 0 1 3 0 1 2 1 1 0 1 2 0 1 0 0 1 1 0 0 0 0 0</counts>
			</dataPoints>
		</scan>
		<scan status="Completed" appendNumber="0" scanAxis="2Theta" mode="Continuous">
			<header>
				<startTimeStamp>2023-05-09T17:41:52-04:00</startTimeStamp>
				<endTimeStamp>2023-05-09T17:56:58-04:00</endTimeStamp>
				<author>
					<name>User</name>
				</author>
				<source>
					<applicationSoftware version="7.1">Data Collector</applicationSoftware>
					<instrumentControlSoftware version="8.2  20201204">EMPYREAN</instrumentControlSoftware>
					<instrumentID>0000000011260721</instrumentID>
				</source>
			</header>
			<dataPoints>
				<positions axis="2Theta" unit="deg">
					<startPosition>74.0168541064312</startPosition>
					<endPosition>77.3641238776477</endPosition>
				</positions>
				<positions axis="Omega" unit="deg">
					<commonPosition>19.4299444960197</commonPosition>
				</positions>
				<positions axis="Phi" unit="deg">
					<commonPosition>-92.99</commonPosition>
				</positions>
				<positions axis="Chi" unit="deg">
					<commonPosition>0</commonPosition>
				</positions>
				<positions axis="Z" unit="mm">
					<commonPosition>8.384</commonPosition>
				</positions>
				<commonCountingTime unit="seconds">0.974</commonCountingTime>
				<counts unit="counts">0 0 0 0 0 0 0 0 1 0 0 0 0 2 0 0 0 1 0 1 2 0 0 0 3 0 0 0 0 0 0 1 0 1 1 0 1 2 0 0 1 0 0 1 1 0 1 0 1 0 0 0 0 0 0 0 1 0 0 0 0 0 1 1 1 1 0 0 0 0 0 0 0 0 0 0 0 0 0 0 0 3 0 0 0 0 0 0 0 0 0 1 1 1 1 0 0 1 0 2 0 0 0 0 1 0 1 0 0 0 0 0 2 0 1 1 1 0 1 0 0 0 1 1 0 0 0 1 1 0 0 0 0 0 0 1 0 0 0 0 0 0 2 0 1 0 0 0 0 0 0 0 0 0 0 0 3 1 0 0 1 0 0 1 1 1 1 0 0 0 0 0 0 1 0 0 0 1 2 1 0 1 0 1 0 0 0 1 0 1 0 0 3 0 0 0 0 0 1 0 0 0 3 1 1 0 0 1 0 0 0 0 0 1 0 0 0 0 0 0 3 0 0 0 0 0 0 0 0 0 0 2 0 1 1 0 1 0 2 0 1 3 0 2 1 1 1 0 0 0 1 0 1 0 1</counts>
			</dataPoints>
		</scan>
		<scan status="Completed" appendNumber="0" scanAxis="2Theta" mode="Continuous">
			<header>
				<startTimeStamp>2023-05-09T17:41:52-04:00</startTimeStamp>
				<endTimeStamp>2023-05-09T17:56:58-04:00</endTimeStamp>
				<author>
					<name>User</name>
				</author>
				<source>
					<applicationSoftware version="7.1">Data Collector</applicationSoftware>
					<instrumentControlSoftware version="8.2  20201204">EMPYREAN</instrumentControlSoftware>
					<instrumentID>0000000011260721</instrumentID>
				</source>
			</header>
			<dataPoints>
				<positions axis="2Theta" unit="deg">
					<startPosition>74.0201366771111</startPosition>
					<endPosition>77.3674064483275</endPosition>
				</positions>
				<positions axis="Omega" unit="deg">
					<commonPosition>19.4315857813596</commonPosition>
				</positions>
				<positions axis="Phi" unit="deg">
					<commonPosition>-92.99</commonPosition>
				</positions>
				<positions axis="Chi" unit="deg">
					<commonPosition>0</commonPosition>
				</positions>
				<positions axis="Z" unit="mm">
					<commonPosition>8.384</commonPosition>
				</positions>
				<commonCountingTime unit="seconds">0.974</commonCountingTime>
				<counts unit="counts">1 2 0 0 1 0 1 0 2 0 0 1 1 2 0 1 0 0 0 0 0 1 1 0 0 0 0 0 1 0 2 2 0 0 1 0 0 1 0 0 0 0 1 0 0 0 0 0 1 0 0 1 0 0 0 2 1 0 0 0 0 0 0 2 0 0 0 0 0 0 0 0 0 1 0 0 0 3 0 0 1 0 0 0 0 0 1 0 0 0 0 0 0 0 0 2 0 0 0 0 0 0 0 1 0 0 0 0 0 1 0 0 0 1 0 0 0 1 1 0 0 1 1 0 1 0 1 0 0 1 0 0 1 0 0 0 1 1 0 0 0 0 1 0 0 0 1 0 0 0 0 0 0 1 0 0 0 1 0 0 1 1 2 0 2 0 0 0 0 0 0 0 1 2 0 0 0 0 3 0 0 1 0 1 1 0 1 0 1 0 0 0 1 0 0 1 0 0 0 0 1 0 0 1 0 0 0 1 0 0 0 1 1 0 2 2 0 2 0 1 1 2 0 0 0 0 1 0 1 1 1 1 0 1 2 0 0 0 1 0 0 0 2 2 0 1 1 0 0 1 0 3 0 0 0</counts>
			</dataPoints>
		</scan>
		<scan status="Completed" appendNumber="0" scanAxis="2Theta" mode="Continuous">
			<header>
				<startTimeStamp>2023-05-09T17:41:52-04:00</startTimeStamp>
				<endTimeStamp>2023-05-09T17:56:58-04:00</endTimeStamp>
				<author>
					<name>User</name>
				</author>
				<source>
					<applicationSoftware version="7.1">Data Collector</applicationSoftware>
					<instrumentControlSoftware version="8.2  20201204">EMPYREAN</instrumentControlSoftware>
					<instrumentID>0000000011260721</instrumentID>
				</source>
			</header>
			<dataPoints>
				<positions axis="2Theta" unit="deg">
					<startPosition>74.0234192477909</startPosition>
					<endPosition>77.3706890190074</endPosition>
				</positions>
				<positions axis="Omega" unit="deg">
					<commonPosition>19.4332270666996</commonPosition>
				</positions>
				<positions axis="Phi" unit="deg">
					<commonPosition>-92.99</commonPosition>
				</positions>
				<positions axis="Chi" unit="deg">
					<commonPosition>0</commonPosition>
				</positions>
				<positions axis="Z" unit="mm">
					<commonPosition>8.384</commonPosition>
				</positions>
				<commonCountingTime unit="seconds">0.974</commonCountingTime>
				<counts unit="counts">0 0 1 0 0 0 0 0 1 0 0 0 2 0 0 1 0 0 1 0 0 1 0 0 1 0 0 0 0 0 0 0 0 0 0 1 1 1 0 0 0 0 0 1 0 0 0 0 1 2 0 1 0 0 0 1 0 1 0 0 0 1 1 0 0 1 1 0 0 0 0 0 1 1 0 0 0 0 0 0 1 0 0 1 1 0 0 0 0 0 1 2 0 0 1 0 0 0 1 0 1 0 1 0 1 1 0 0 1 0 0 0 0 0 0 1 2 0 2 0 0 0 0 0 0 1 0 0 0 1 0 0 0 0 0 1 0 1 1 0 0 0 1 0 0 0 0 0 0 0 0 0 1 0 1 0 2 0 0 0 0 2 1 2 1 1 1 0 0 0 0 0 0 0 0 1 1 0 0 0 0 2 0 0 2 0 0 1 0 0 0 1 1 0 1 1 0 0 0 0 1 0 1 0 0 0 0 1 0 0 0 0 0 1 0 0 0 0 0 0 0 0 1 0 0 1 2 0 0 0 0 2 0 0 0 0 0 0 0 1 1 0 2 0 0 0 0 1 1 1 1 0 0 0 0</counts>
			</dataPoints>
		</scan>
		<scan status="Completed" appendNumber="0" scanAxis="2Theta" mode="Continuous">
			<header>
				<startTimeStamp>2023-05-09T17:41:52-04:00</startTimeStamp>
				<endTimeStamp>2023-05-09T17:56:58-04:00</endTimeStamp>
				<author>
					<name>User</name>
				</author>
				<source>
					<applicationSoftware version="7.1">Data Collector</applicationSoftware>
					<instrumentControlSoftware version="8.2  20201204">EMPYREAN</instrumentControlSoftware>
					<instrumentID>0000000011260721</instrumentID>
				</source>
			</header>
			<dataPoints>
				<positions axis="2Theta" unit="deg">
					<startPosition>74.0267018184707</startPosition>
					<endPosition>77.3739715896872</endPosition>
				</positions>
				<positions axis="Omega" unit="deg">
					<commonPosition>19.4348683520395</commonPosition>
				</positions>
				<positions axis="Phi" unit="deg">
					<commonPosition>-92.99</commonPosition>
				</positions>
				<positions axis="Chi" unit="deg">
					<commonPosition>0</commonPosition>
				</positions>
				<positions axis="Z" unit="mm">
					<commonPosition>8.384</commonPosition>
				</positions>
				<commonCountingTime unit="seconds">0.974</commonCountingTime>
				<counts unit="counts">1 0 0 0 1 0 2 1 1 1 0 0 0 0 1 0 0 0 0 2 0 0 0 0 1 0 0 1 0 0 1 0 1 1 0 1 0 0 0 0 1 0 0 1 0 0 0 1 0 0 0 0 0 0 0 0 2 0 1 0 0 0 0 0 0 0 0 0 0 1 1 0 0 0 0 1 0 1 0 1 0 0 1 0 0 0 0 0 2 0 1 1 0 1 0 0 0 0 0 0 0 0 0 1 1 0 0 0 0 0 0 0 0 0 0 0 0 0 0 0 0 0 0 0 0 2 1 0 0 1 0 0 0 1 0 0 0 0 0 2 0 0 1 0 1 1 0 0 0 0 0 0 1 2 0 0 0 0 1 0 1 0 0 0 0 0 1 1 2 0 0 0 0 0 0 0 0 0 0 0 0 2 1 1 1 0 2 0 0 0 1 0 1 1 1 1 2 1 1 1 0 0 1 0 0 0 1 0 1 0 2 0 1 1 0 1 0 0 0 0 1 3 0 0 0 0 0 1 1 3 2 0 0 2 2 0 0 0 0 0 0 0 0 0 0 1 0 2 0 1 0 0 1 1 1</counts>
			</dataPoints>
		</scan>
		<scan status="Completed" appendNumber="0" scanAxis="2Theta" mode="Continuous">
			<header>
				<startTimeStamp>2023-05-09T17:41:52-04:00</startTimeStamp>
				<endTimeStamp>2023-05-09T17:56:58-04:00</endTimeStamp>
				<author>
					<name>User</name>
				</author>
				<source>
					<applicationSoftware version="7.1">Data Collector</applicationSoftware>
					<instrumentControlSoftware version="8.2  20201204">EMPYREAN</instrumentControlSoftware>
					<instrumentID>0000000011260721</instrumentID>
				</source>
			</header>
			<dataPoints>
				<positions axis="2Theta" unit="deg">
					<startPosition>74.0299843891505</startPosition>
					<endPosition>77.377254160367</endPosition>
				</positions>
				<positions axis="Omega" unit="deg">
					<commonPosition>19.4365096373794</commonPosition>
				</positions>
				<positions axis="Phi" unit="deg">
					<commonPosition>-92.99</commonPosition>
				</positions>
				<positions axis="Chi" unit="deg">
					<commonPosition>0</commonPosition>
				</positions>
				<positions axis="Z" unit="mm">
					<commonPosition>8.384</commonPosition>
				</positions>
				<commonCountingTime unit="seconds">0.974</commonCountingTime>
				<counts unit="counts">0 0 1 1 1 0 1 2 0 0 1 0 0 0 0 0 0 0 0 1 0 0 0 0 2 0 0 0 0 0 1 0 0 0 0 0 0 0 0 1 1 1 1 0 0 0 1 0 0 0 0 0 1 0 0 0 0 0 0 0 0 1 0 0 0 0 0 1 0 1 0 1 1 0 0 0 1 0 1 0 0 1 0 0 1 2 0 0 0 0 0 0 1 0 0 1 0 0 0 0 0 0 0 0 1 1 0 0 0 0 0 0 0 0 0 0 0 0 1 0 0 0 0 0 1 0 0 0 0 0 0 0 1 0 0 0 0 0 0 0 0 0 1 0 0 0 1 0 0 0 0 0 0 1 0 0 0 0 0 1 1 1 2 0 0 0 0 0 0 1 0 0 2 0 0 0 1 0 0 1 1 2 0 0 0 2 0 1 0 1 0 0 0 0 2 0 0 0 0 0 1 0 0 1 0 0 3 1 0 0 0 1 0 0 0 0 0 1 2 1 0 1 1 0 0 0 0 0 1 0 0 1 1 1 1 1 1 0 1 0 0 1 2 1 0 0 0 1 1 1 0 2 0 0 0</counts>
			</dataPoints>
		</scan>
		<scan status="Completed" appendNumber="0" scanAxis="2Theta" mode="Continuous">
			<header>
				<startTimeStamp>2023-05-09T17:41:52-04:00</startTimeStamp>
				<endTimeStamp>2023-05-09T17:56:58-04:00</endTimeStamp>
				<author>
					<name>User</name>
				</author>
				<source>
					<applicationSoftware version="7.1">Data Collector</applicationSoftware>
					<instrumentControlSoftware version="8.2  20201204">EMPYREAN</instrumentControlSoftware>
					<instrumentID>0000000011260721</instrumentID>
				</source>
			</header>
			<dataPoints>
				<positions axis="2Theta" unit="deg">
					<startPosition>74.0332669598304</startPosition>
					<endPosition>77.3805367310468</endPosition>
				</positions>
				<positions axis="Omega" unit="deg">
					<commonPosition>19.4381509227193</commonPosition>
				</positions>
				<positions axis="Phi" unit="deg">
					<commonPosition>-92.99</commonPosition>
				</positions>
				<positions axis="Chi" unit="deg">
					<commonPosition>0</commonPosition>
				</positions>
				<positions axis="Z" unit="mm">
					<commonPosition>8.384</commonPosition>
				</positions>
				<commonCountingTime unit="seconds">0.974</commonCountingTime>
				<counts unit="counts">0 1 0 0 2 0 0 0 0 1 0 0 0 0 0 0 1 2 1 0 0 1 1 0 2 1 0 1 0 0 0 0 1 0 1 0 0 1 0 0 0 0 1 0 0 1 0 0 0 0 0 0 1 1 0 0 1 1 0 1 0 0 0 1 1 2 0 0 0 0 1 1 0 0 0 0 0 0 1 0 0 0 0 1 0 0 1 0 0 0 0 0 1 0 1 0 1 0 1 1 1 0 1 0 1 0 0 2 1 0 0 0 0 1 0 0 1 0 0 1 0 0 0 0 0 0 0 0 0 2 0 1 0 0 0 1 0 0 0 0 0 2 0 0 0 2 0 0 0 0 1 0 0 0 0 0 0 0 2 1 0 1 0 0 0 0 0 1 1 0 2 0 1 0 0 0 0 0 0 1 0 1 1 0 0 0 0 0 0 0 0 0 0 1 0 0 0 1 0 0 0 0 0 0 0 0 1 1 0 0 0 2 0 1 0 0 0 1 0 0 0 0 0 0 1 0 1 1 0 0 0 1 2 1 1 1 2 2 1 0 0 0 0 0 0 1 3 1 0 0 1 2 1 0 0</counts>
			</dataPoints>
		</scan>
		<scan status="Completed" appendNumber="0" scanAxis="2Theta" mode="Continuous">
			<header>
				<startTimeStamp>2023-05-09T17:41:52-04:00</startTimeStamp>
				<endTimeStamp>2023-05-09T17:56:58-04:00</endTimeStamp>
				<author>
					<name>User</name>
				</author>
				<source>
					<applicationSoftware version="7.1">Data Collector</applicationSoftware>
					<instrumentControlSoftware version="8.2  20201204">EMPYREAN</instrumentControlSoftware>
					<instrumentID>0000000011260721</instrumentID>
				</source>
			</header>
			<dataPoints>
				<positions axis="2Theta" unit="deg">
					<startPosition>74.0365495305102</startPosition>
					<endPosition>77.3838193017267</endPosition>
				</positions>
				<positions axis="Omega" unit="deg">
					<commonPosition>19.4397922080592</commonPosition>
				</positions>
				<positions axis="Phi" unit="deg">
					<commonPosition>-92.99</commonPosition>
				</positions>
				<positions axis="Chi" unit="deg">
					<commonPosition>0</commonPosition>
				</positions>
				<positions axis="Z" unit="mm">
					<commonPosition>8.384</commonPosition>
				</positions>
				<commonCountingTime unit="seconds">0.974</commonCountingTime>
				<counts unit="counts">0 0 1 0 2 0 0 0 0 0 0 1 0 0 0 0 0 1 0 1 0 1 0 0 0 0 0 0 0 0 1 1 0 1 0 0 0 0 1 1 1 0 1 0 0 0 0 0 0 0 1 2 1 0 0 0 0 1 1 0 1 0 0 0 0 0 0 1 0 2 0 0 1 0 0 0 0 0 0 0 0 1 0 1 2 2 0 0 0 0 0 0 0 2 0 1 1 0 1 1 0 0 1 0 0 1 1 0 0 0 0 0 0 0 1 0 1 0 0 0 1 0 0 0 0 0 0 0 1 0 0 1 0 1 2 0 0 0 2 0 2 0 1 0 2 1 0 0 1 0 0 0 0 2 1 1 0 0 0 0 0 0 0 0 0 0 0 0 0 1 0 0 0 0 0 0 0 0 2 1 0 1 2 0 2 0 0 0 0 2 0 2 0 0 1 0 0 1 0 0 1 0 1 1 0 0 0 1 0 0 0 0 0 0 2 1 0 0 0 0 0 0 0 1 2 0 0 1 0 1 0 0 0 1 0 1 0 0 0 1 1 0 1 0 0 0 0 0 0 0 0 0 1 2 0</counts>
			</dataPoints>
		</scan>
		<scan status="Completed" appendNumber="0" scanAxis="2Theta" mode="Continuous">
			<header>
				<startTimeStamp>2023-05-09T17:41:52-04:00</startTimeStamp>
				<endTimeStamp>2023-05-09T17:56:58-04:00</endTimeStamp>
				<author>
					<name>User</name>
				</author>
				<source>
					<applicationSoftware version="7.1">Data Collector</applicationSoftware>
					<instrumentControlSoftware version="8.2  20201204">EMPYREAN</instrumentControlSoftware>
					<instrumentID>0000000011260721</instrumentID>
				</source>
			</header>
			<dataPoints>
				<positions axis="2Theta" unit="deg">
					<startPosition>74.03983210119</startPosition>
					<endPosition>77.3871018724065</endPosition>
				</positions>
				<positions axis="Omega" unit="deg">
					<commonPosition>19.4414334933991</commonPosition>
				</positions>
				<positions axis="Phi" unit="deg">
					<commonPosition>-92.99</commonPosition>
				</positions>
				<positions axis="Chi" unit="deg">
					<commonPosition>0</commonPosition>
				</positions>
				<positions axis="Z" unit="mm">
					<commonPosition>8.384</commonPosition>
				</positions>
				<commonCountingTime unit="seconds">0.974</commonCountingTime>
				<counts unit="counts">0 0 0 0 0 0 3 0 1 1 0 1 0 0 1 1 0 0 2 1 0 0 0 0 0 0 0 1 0 0 0 0 0 0 2 0 0 0 1 0 0 0 1 0 0 0 0 0 0 1 0 1 0 1 1 0 0 3 0 0 0 0 1 0 0 0 0 0 1 0 0 1 0 0 0 0 0 1 0 0 0 0 0 0 0 0 0 1 1 1 0 0 0 0 1 0 0 0 0 0 0 1 1 0 1 0 0 0 0 0 0 0 1 0 0 0 0 0 1 1 0 0 0 0 0 0 0 0 0 0 1 1 0 1 0 0 0 2 1 0 0 0 0 1 0 0 0 0 1 0 0 1 0 0 0 0 0 2 1 0 2 2 1 0 1 1 0 0 0 0 0 0 0 1 0 0 0 1 0 1 0 1 1 0 1 1 0 0 2 0 0 1 0 0 0 0 1 1 0 0 1 0 1 1 0 1 1 0 0 0 0 0 0 0 0 1 1 0 0 0 0 0 0 0 3 1 1 1 0 2 0 0 1 0 1 0 0 1 0 0 0 1 0 1 0 0 0 0 0 0 0 0 0 0 2</counts>
			</dataPoints>
		</scan>
		<scan status="Completed" appendNumber="0" scanAxis="2Theta" mode="Continuous">
			<header>
				<startTimeStamp>2023-05-09T17:41:52-04:00</startTimeStamp>
				<endTimeStamp>2023-05-09T17:56:58-04:00</endTimeStamp>
				<author>
					<name>User</name>
				</author>
				<source>
					<applicationSoftware version="7.1">Data Collector</applicationSoftware>
					<instrumentControlSoftware version="8.2  20201204">EMPYREAN</instrumentControlSoftware>
					<instrumentID>0000000011260721</instrumentID>
				</source>
			</header>
			<dataPoints>
				<positions axis="2Theta" unit="deg">
					<startPosition>74.0431146718698</startPosition>
					<endPosition>77.3903844430863</endPosition>
				</positions>
				<positions axis="Omega" unit="deg">
					<commonPosition>19.443074778739</commonPosition>
				</positions>
				<positions axis="Phi" unit="deg">
					<commonPosition>-92.99</commonPosition>
				</positions>
				<positions axis="Chi" unit="deg">
					<commonPosition>0</commonPosition>
				</positions>
				<positions axis="Z" unit="mm">
					<commonPosition>8.384</commonPosition>
				</positions>
				<commonCountingTime unit="seconds">0.974</commonCountingTime>
				<counts unit="counts">0 0 0 0 0 0 0 0 3 1 0 1 0 1 1 0 0 0 0 1 0 1 1 0 0 0 1 0 1 0 0 0 1 1 0 0 1 0 0 1 0 1 0 0 0 0 0 0 0 0 1 0 1 0 0 0 0 1 0 0 0 0 0 0 0 0 0 2 0 0 0 0 0 0 0 0 0 2 0 0 1 0 0 0 0 1 1 0 0 0 0 0 0 0 0 1 2 0 0 0 1 1 0 0 0 1 0 0 0 1 1 0 0 0 0 0 0 0 0 0 0 0 0 0 0 1 0 0 1 1 0 0 1 0 0 0 0 1 0 1 0 0 0 1 0 1 0 0 0 0 2 0 0 0 0 1 1 0 0 0 2 0 1 0 1 0 1 1 2 1 0 0 1 0 0 1 1 0 0 0 0 0 0 0 0 0 1 1 1 0 0 0 0 0 2 0 0 1 0 0 2 0 0 1 1 0 0 1 1 2 0 0 0 1 1 1 0 0 0 0 0 0 0 0 0 0 0 0 1 0 1 0 2 0 1 0 1 1 0 0 0 2 0 0 0 0 0 0 0 0 0 0 0 0 0</counts>
			</dataPoints>
		</scan>
		<scan status="Completed" appendNumber="0" scanAxis="2Theta" mode="Continuous">
			<header>
				<startTimeStamp>2023-05-09T17:41:52-04:00</startTimeStamp>
				<endTimeStamp>2023-05-09T17:56:58-04:00</endTimeStamp>
				<author>
					<name>User</name>
				</author>
				<source>
					<applicationSoftware version="7.1">Data Collector</applicationSoftware>
					<instrumentControlSoftware version="8.2  20201204">EMPYREAN</instrumentControlSoftware>
					<instrumentID>0000000011260721</instrumentID>
				</source>
			</header>
			<dataPoints>
				<positions axis="2Theta" unit="deg">
					<startPosition>74.0463972425497</startPosition>
					<endPosition>77.3936670137661</endPosition>
				</positions>
				<positions axis="Omega" unit="deg">
					<commonPosition>19.4447160640789</commonPosition>
				</positions>
				<positions axis="Phi" unit="deg">
					<commonPosition>-92.99</commonPosition>
				</positions>
				<positions axis="Chi" unit="deg">
					<commonPosition>0</commonPosition>
				</positions>
				<positions axis="Z" unit="mm">
					<commonPosition>8.384</commonPosition>
				</positions>
				<commonCountingTime unit="seconds">0.974</commonCountingTime>
				<counts unit="counts">0 1 0 0 0 0 0 0 0 1 0 0 1 0 0 0 0 1 0 0 0 0 0 0 0 0 0 1 0 1 0 0 0 0 0 0 0 0 0 0 0 1 1 0 0 0 0 0 1 0 0 0 1 0 0 0 0 0 2 2 0 0 0 1 2 0 0 0 1 0 0 1 0 0 1 0 0 0 0 0 0 0 0 0 0 1 1 0 1 0 0 0 1 0 1 0 0 0 0 0 0 0 0 0 0 1 1 1 0 1 0 0 0 0 0 1 1 0 0 1 1 0 0 0 1 0 0 1 0 0 0 0 1 1 1 0 0 0 0 0 0 0 0 1 3 0 0 0 0 0 0 0 0 1 0 0 0 0 1 1 0 0 1 2 1 2 0 0 0 0 1 3 0 1 0 0 0 0 0 0 0 0 1 1 1 0 2 1 1 1 0 0 1 0 0 1 0 0 1 0 0 1 2 0 1 0 0 1 0 1 0 0 0 0 0 0 1 1 0 0 1 1 0 0 0 0 0 1 1 0 0 0 1 1 0 0 3 0 1 1 1 1 0 1 1 0 0 1 0 1 0 0 1 0 0</counts>
			</dataPoints>
		</scan>
		<scan status="Completed" appendNumber="0" scanAxis="2Theta" mode="Continuous">
			<header>
				<startTimeStamp>2023-05-09T17:41:52-04:00</startTimeStamp>
				<endTimeStamp>2023-05-09T17:56:58-04:00</endTimeStamp>
				<author>
					<name>User</name>
				</author>
				<source>
					<applicationSoftware version="7.1">Data Collector</applicationSoftware>
					<instrumentControlSoftware version="8.2  20201204">EMPYREAN</instrumentControlSoftware>
					<instrumentID>0000000011260721</instrumentID>
				</source>
			</header>
			<dataPoints>
				<positions axis="2Theta" unit="deg">
					<startPosition>74.0496798132295</startPosition>
					<endPosition>77.396949584446</endPosition>
				</positions>
				<positions axis="Omega" unit="deg">
					<commonPosition>19.4463573494189</commonPosition>
				</positions>
				<positions axis="Phi" unit="deg">
					<commonPosition>-92.99</commonPosition>
				</positions>
				<positions axis="Chi" unit="deg">
					<commonPosition>0</commonPosition>
				</positions>
				<positions axis="Z" unit="mm">
					<commonPosition>8.384</commonPosition>
				</positions>
				<commonCountingTime unit="seconds">0.974</commonCountingTime>
				<counts unit="counts">1 0 0 0 0 0 1 0 0 0 0 0 0 1 0 0 0 0 0 0 0 1 1 0 0 0 0 0 2 0 1 1 0 0 0 0 0 0 1 0 0 0 2 0 1 0 0 1 0 0 0 0 0 0 1 0 0 0 2 1 0 0 0 0 0 0 0 1 0 0 1 0 0 1 1 0 0 0 0 0 0 0 1 0 1 0 0 0 1 0 0 0 0 0 0 0 0 1 1 1 0 0 0 0 0 0 0 0 0 0 0 1 0 0 0 1 1 0 1 0 1 0 0 0 0 0 1 1 1 0 0 0 0 0 0 0 0 1 1 1 1 0 1 0 1 0 0 1 0 0 0 1 1 0 0 0 0 0 1 1 0 0 0 1 0 1 1 0 0 1 1 0 0 0 1 0 0 0 0 0 0 1 0 1 0 0 1 1 1 0 0 0 0 1 0 0 0 0 1 0 2 0 0 0 0 1 1 0 0 0 0 0 0 0 0 0 0 0 0 0 1 0 0 0 0 0 1 0 2 0 1 1 1 2 0 0 0 0 0 0 2 0 1 1 0 0 2 0 2 0 0 0 0 0 1</counts>
			</dataPoints>
		</scan>
		<scan status="Completed" appendNumber="0" scanAxis="2Theta" mode="Continuous">
			<header>
				<startTimeStamp>2023-05-09T17:41:52-04:00</startTimeStamp>
				<endTimeStamp>2023-05-09T17:56:58-04:00</endTimeStamp>
				<author>
					<name>User</name>
				</author>
				<source>
					<applicationSoftware version="7.1">Data Collector</applicationSoftware>
					<instrumentControlSoftware version="8.2  20201204">EMPYREAN</instrumentControlSoftware>
					<instrumentID>0000000011260721</instrumentID>
				</source>
			</header>
			<dataPoints>
				<positions axis="2Theta" unit="deg">
					<startPosition>74.0529623839093</startPosition>
					<endPosition>77.4002321551258</endPosition>
				</positions>
				<positions axis="Omega" unit="deg">
					<commonPosition>19.4479986347588</commonPosition>
				</positions>
				<positions axis="Phi" unit="deg">
					<commonPosition>-92.99</commonPosition>
				</positions>
				<positions axis="Chi" unit="deg">
					<commonPosition>0</commonPosition>
				</positions>
				<positions axis="Z" unit="mm">
					<commonPosition>8.384</commonPosition>
				</positions>
				<commonCountingTime unit="seconds">0.974</commonCountingTime>
				<counts unit="counts">0 0 0 1 0 0 0 0 1 1 0 0 1 4 2 0 0 0 0 1 1 0 0 0 1 0 1 0 0 0 0 1 0 0 0 1 0 0 0 1 2 0 0 0 1 0 2 0 0 0 0 0 1 0 0 0 1 0 1 0 0 0 0 1 0 0 0 0 0 3 0 1 0 1 0 0 0 0 0 0 0 0 0 0 0 0 0 0 0 1 1 0 0 0 1 0 0 1 0 1 0 0 0 1 0 0 1 0 1 0 1 0 2 1 0 2 1 1 0 0 0 0 0 0 3 0 0 0 0 0 0 0 0 1 0 0 2 0 1 0 0 2 0 1 0 0 1 0 1 2 2 0 1 2 1 2 2 0 0 1 1 0 0 0 0 0 0 0 1 1 1 0 0 1 1 0 0 0 0 1 0 0 1 0 0 0 0 1 0 0 0 1 0 0 0 0 0 0 0 0 0 0 0 0 0 0 0 0 0 0 1 0 0 0 1 1 0 0 2 0 0 1 0 0 0 1 1 0 0 0 2 1 0 0 0 1 0 1 1 0 1 1 0 1 0 1 1 1 1 0 1 0 0 0 1</counts>
			</dataPoints>
		</scan>
		<scan status="Completed" appendNumber="0" scanAxis="2Theta" mode="Continuous">
			<header>
				<startTimeStamp>2023-05-09T17:41:52-04:00</startTimeStamp>
				<endTimeStamp>2023-05-09T17:56:58-04:00</endTimeStamp>
				<author>
					<name>User</name>
				</author>
				<source>
					<applicationSoftware version="7.1">Data Collector</applicationSoftware>
					<instrumentControlSoftware version="8.2  20201204">EMPYREAN</instrumentControlSoftware>
					<instrumentID>0000000011260721</instrumentID>
				</source>
			</header>
			<dataPoints>
				<positions axis="2Theta" unit="deg">
					<startPosition>74.0562449545891</startPosition>
					<endPosition>77.4035147258056</endPosition>
				</positions>
				<positions axis="Omega" unit="deg">
					<commonPosition>19.4496399200987</commonPosition>
				</positions>
				<positions axis="Phi" unit="deg">
					<commonPosition>-92.99</commonPosition>
				</positions>
				<positions axis="Chi" unit="deg">
					<commonPosition>0</commonPosition>
				</positions>
				<positions axis="Z" unit="mm">
					<commonPosition>8.384</commonPosition>
				</positions>
				<commonCountingTime unit="seconds">0.974</commonCountingTime>
				<counts unit="counts">1 0 2 1 1 0 0 0 0 0 2 0 0 0 0 1 1 1 0 0 0 0 0 0 0 0 0 0 0 0 1 1 0 0 2 1 0 0 0 0 0 0 1 0 0 0 0 0 1 1 0 0 0 0 1 0 1 0 0 0 0 0 0 0 1 0 0 0 0 0 0 1 0 0 1 0 0 0 0 0 1 0 1 0 0 0 0 0 1 0 1 0 0 2 0 0 0 0 0 0 0 0 0 0 0 0 0 0 0 0 0 0 0 2 0 0 0 0 1 0 0 0 0 0 1 1 0 0 0 1 0 1 1 0 0 1 0 1 0 0 1 0 0 0 0 0 0 1 0 1 0 0 0 1 0 0 1 0 0 0 1 3 0 0 2 0 0 1 0 0 0 0 0 0 1 0 2 1 1 1 1 0 1 0 0 1 0 1 0 0 2 0 0 1 0 1 0 0 0 0 0 0 0 0 0 1 1 1 0 0 1 0 0 2 1 1 0 2 0 1 2 2 0 0 0 0 0 0 0 0 3 4 1 0 0 0 0 1 1 0 0 0 2 1 1 0 0 0 0 1 0 0 0 0 1</counts>
			</dataPoints>
		</scan>
		<scan status="Completed" appendNumber="0" scanAxis="2Theta" mode="Continuous">
			<header>
				<startTimeStamp>2023-05-09T17:41:52-04:00</startTimeStamp>
				<endTimeStamp>2023-05-09T17:56:58-04:00</endTimeStamp>
				<author>
					<name>User</name>
				</author>
				<source>
					<applicationSoftware version="7.1">Data Collector</applicationSoftware>
					<instrumentControlSoftware version="8.2  20201204">EMPYREAN</instrumentControlSoftware>
					<instrumentID>0000000011260721</instrumentID>
				</source>
			</header>
			<dataPoints>
				<positions axis="2Theta" unit="deg">
					<startPosition>74.059527525269</startPosition>
					<endPosition>77.4067972964854</endPosition>
				</positions>
				<positions axis="Omega" unit="deg">
					<commonPosition>19.4512812054386</commonPosition>
				</positions>
				<positions axis="Phi" unit="deg">
					<commonPosition>-92.99</commonPosition>
				</positions>
				<positions axis="Chi" unit="deg">
					<commonPosition>0</commonPosition>
				</positions>
				<positions axis="Z" unit="mm">
					<commonPosition>8.384</commonPosition>
				</positions>
				<commonCountingTime unit="seconds">0.974</commonCountingTime>
				<counts unit="counts">0 0 0 0 1 0 0 0 1 1 0 0 0 0 0 1 0 0 0 1 0 2 2 1 0 0 0 0 0 0 0 0 1 0 0 1 0 0 0 1 0 0 0 0 0 1 0 0 1 0 0 2 1 0 0 1 1 0 0 0 0 0 0 0 0 0 0 0 1 0 0 0 0 0 0 0 0 0 0 0 1 0 0 0 0 1 0 1 1 0 0 1 0 1 0 1 0 0 0 0 0 1 0 1 0 0 0 0 1 1 0 1 0 0 1 1 1 2 0 0 0 2 0 0 1 1 0 0 0 0 0 0 0 0 1 0 1 0 0 0 0 1 0 1 0 0 5 0 0 0 0 0 0 0 0 0 1 0 1 0 0 1 2 0 0 0 0 0 1 2 0 0 1 1 0 2 0 0 0 1 0 1 0 0 0 1 0 0 0 1 2 0 0 1 0 1 0 1 0 0 0 1 0 0 0 1 0 0 0 0 0 0 0 1 1 1 0 1 0 0 1 0 0 1 1 0 1 0 0 0 1 0 4 1 0 0 0 0 0 0 0 1 0 0 0 0 3 0 0 0 0 0 0 0 0</counts>
			</dataPoints>
		</scan>
		<scan status="Completed" appendNumber="0" scanAxis="2Theta" mode="Continuous">
			<header>
				<startTimeStamp>2023-05-09T17:41:52-04:00</startTimeStamp>
				<endTimeStamp>2023-05-09T17:56:58-04:00</endTimeStamp>
				<author>
					<name>User</name>
				</author>
				<source>
					<applicationSoftware version="7.1">Data Collector</applicationSoftware>
					<instrumentControlSoftware version="8.2  20201204">EMPYREAN</instrumentControlSoftware>
					<instrumentID>0000000011260721</instrumentID>
				</source>
			</header>
			<dataPoints>
				<positions axis="2Theta" unit="deg">
					<startPosition>74.0628100959488</startPosition>
					<endPosition>77.4100798671653</endPosition>
				</positions>
				<positions axis="Omega" unit="deg">
					<commonPosition>19.4529224907785</commonPosition>
				</positions>
				<positions axis="Phi" unit="deg">
					<commonPosition>-92.99</commonPosition>
				</positions>
				<positions axis="Chi" unit="deg">
					<commonPosition>0</commonPosition>
				</positions>
				<positions axis="Z" unit="mm">
					<commonPosition>8.384</commonPosition>
				</positions>
				<commonCountingTime unit="seconds">0.974</commonCountingTime>
				<counts unit="counts">0 0 1 0 0 0 0 0 1 0 0 0 1 0 1 0 1 1 0 0 0 1 1 0 0 0 0 0 0 0 1 0 1 0 0 0 2 0 0 0 0 0 0 0 0 1 0 3 0 0 0 0 0 0 0 0 0 0 0 1 0 0 0 0 0 0 0 0 0 0 0 0 0 0 1 0 1 0 0 0 0 0 0 1 1 1 0 0 2 0 2 0 0 0 0 0 0 1 0 0 0 0 0 2 0 0 0 0 0 0 0 1 1 0 0 0 0 0 0 2 2 0 2 1 1 0 0 0 1 1 0 0 0 0 0 0 1 1 0 1 1 0 1 0 1 1 0 0 1 2 0 0 0 0 0 1 1 0 1 1 1 0 1 0 1 1 0 0 1 0 0 0 0 0 0 1 0 2 0 0 0 2 1 2 0 1 0 0 1 1 1 0 1 0 0 0 0 1 0 1 1 1 0 1 0 0 0 1 0 1 1 0 1 0 0 0 0 2 0 0 0 0 1 0 0 0 0 2 1 1 0 0 0 0 2 1 0 0 0 1 0 0 0 0 0 0 0 1 0 0 1 0 0 1 0</counts>
			</dataPoints>
		</scan>
		<scan status="Completed" appendNumber="0" scanAxis="2Theta" mode="Continuous">
			<header>
				<startTimeStamp>2023-05-09T17:41:52-04:00</startTimeStamp>
				<endTimeStamp>2023-05-09T17:56:58-04:00</endTimeStamp>
				<author>
					<name>User</name>
				</author>
				<source>
					<applicationSoftware version="7.1">Data Collector</applicationSoftware>
					<instrumentControlSoftware version="8.2  20201204">EMPYREAN</instrumentControlSoftware>
					<instrumentID>0000000011260721</instrumentID>
				</source>
			</header>
			<dataPoints>
				<positions axis="2Theta" unit="deg">
					<startPosition>74.0660926666286</startPosition>
					<endPosition>77.4133624378451</endPosition>
				</positions>
				<positions axis="Omega" unit="deg">
					<commonPosition>19.4545637761184</commonPosition>
				</positions>
				<positions axis="Phi" unit="deg">
					<commonPosition>-92.99</commonPosition>
				</positions>
				<positions axis="Chi" unit="deg">
					<commonPosition>0</commonPosition>
				</positions>
				<positions axis="Z" unit="mm">
					<commonPosition>8.384</commonPosition>
				</positions>
				<commonCountingTime unit="seconds">0.974</commonCountingTime>
				<counts unit="counts">0 3 0 0 0 0 0 0 0 0 0 1 0 0 0 0 0 1 0 0 0 0 0 1 0 0 0 1 1 0 0 1 0 0 0 1 0 1 0 0 0 0 0 1 1 1 0 0 0 0 0 0 0 0 0 1 0 2 0 0 0 0 0 1 0 1 0 1 0 0 0 0 0 1 0 0 0 0 1 0 1 0 0 0 0 2 2 0 0 1 0 0 1 0 0 1 0 0 0 0 1 1 0 0 0 0 0 1 0 0 0 1 1 0 0 0 0 0 0 0 0 0 0 0 1 0 1 0 1 0 1 1 0 2 0 1 0 1 0 0 0 0 0 0 0 0 0 0 1 1 0 0 0 1 0 0 0 1 0 0 2 0 1 1 0 0 0 0 0 0 0 0 0 0 0 0 0 2 1 0 0 1 0 2 0 1 1 1 0 0 1 0 0 2 0 1 1 1 0 0 0 0 0 0 0 0 0 1 1 1 2 1 0 0 1 0 0 1 0 0 0 1 0 0 0 0 0 0 1 1 0 0 2 1 2 0 1 1 0 1 1 0 0 1 1 0 1 0 0 0 0 0 0 1 0</counts>
			</dataPoints>
		</scan>
		<scan status="Completed" appendNumber="0" scanAxis="2Theta" mode="Continuous">
			<header>
				<startTimeStamp>2023-05-09T17:41:52-04:00</startTimeStamp>
				<endTimeStamp>2023-05-09T17:56:58-04:00</endTimeStamp>
				<author>
					<name>User</name>
				</author>
				<source>
					<applicationSoftware version="7.1">Data Collector</applicationSoftware>
					<instrumentControlSoftware version="8.2  20201204">EMPYREAN</instrumentControlSoftware>
					<instrumentID>0000000011260721</instrumentID>
				</source>
			</header>
			<dataPoints>
				<positions axis="2Theta" unit="deg">
					<startPosition>74.0693752373084</startPosition>
					<endPosition>77.4166450085249</endPosition>
				</positions>
				<positions axis="Omega" unit="deg">
					<commonPosition>19.4562050614583</commonPosition>
				</positions>
				<positions axis="Phi" unit="deg">
					<commonPosition>-92.99</commonPosition>
				</positions>
				<positions axis="Chi" unit="deg">
					<commonPosition>0</commonPosition>
				</positions>
				<positions axis="Z" unit="mm">
					<commonPosition>8.384</commonPosition>
				</positions>
				<commonCountingTime unit="seconds">0.974</commonCountingTime>
				<counts unit="counts">1 0 0 0 0 0 1 1 1 1 0 0 0 0 0 0 0 0 0 0 0 0 1 0 0 0 0 0 0 1 0 0 1 1 2 0 0 0 1 0 0 1 0 0 1 0 0 0 0 0 0 0 0 1 1 0 0 2 0 1 0 0 0 0 0 0 0 0 0 0 1 0 1 0 1 0 0 1 0 0 1 0 0 0 0 1 0 2 1 1 0 0 0 0 0 0 1 0 0 0 0 0 0 0 1 0 1 4 0 1 0 0 0 0 2 0 0 3 0 0 0 0 0 0 0 0 1 0 0 0 0 0 0 0 0 1 0 1 1 0 2 0 0 0 0 3 0 0 1 1 2 0 0 0 0 1 0 0 0 1 1 1 2 1 1 1 0 0 0 1 1 1 0 0 1 1 1 0 1 0 0 0 1 0 0 2 1 0 0 1 4 0 0 0 0 2 1 1 0 1 0 1 0 0 0 0 1 1 1 0 0 0 2 0 0 0 0 0 0 0 0 0 1 0 1 0 1 2 1 0 1 0 1 0 0 2 2 1 1 0 1 0 0 0 0 0 1 1 2 0 0 0 1 0 0</counts>
			</dataPoints>
		</scan>
		<scan status="Completed" appendNumber="0" scanAxis="2Theta" mode="Continuous">
			<header>
				<startTimeStamp>2023-05-09T17:41:52-04:00</startTimeStamp>
				<endTimeStamp>2023-05-09T17:56:58-04:00</endTimeStamp>
				<author>
					<name>User</name>
				</author>
				<source>
					<applicationSoftware version="7.1">Data Collector</applicationSoftware>
					<instrumentControlSoftware version="8.2  20201204">EMPYREAN</instrumentControlSoftware>
					<instrumentID>0000000011260721</instrumentID>
				</source>
			</header>
			<dataPoints>
				<positions axis="2Theta" unit="deg">
					<startPosition>74.0726578079883</startPosition>
					<endPosition>77.4199275792047</endPosition>
				</positions>
				<positions axis="Omega" unit="deg">
					<commonPosition>19.4578463467982</commonPosition>
				</positions>
				<positions axis="Phi" unit="deg">
					<commonPosition>-92.99</commonPosition>
				</positions>
				<positions axis="Chi" unit="deg">
					<commonPosition>0</commonPosition>
				</positions>
				<positions axis="Z" unit="mm">
					<commonPosition>8.384</commonPosition>
				</positions>
				<commonCountingTime unit="seconds">0.974</commonCountingTime>
[...]
					<commonPosition>0</commonPosition>
				</positions>
				<positions axis="Z" unit="mm">
					<commonPosition>8.384</commonPosition>
				</positions>
				<commonCountingTime unit="seconds">0.974</commonCountingTime>
				<counts unit="counts">0 4 0 1 1 0 0 0 0 2 0 1 1 0 1 1 1 0 1 0 0 0 0 1 0 0 0 0 0 0 0 2 1 0 2 1 0 0 0 0 0 0 2 0 0 0 1 0 0 0 0 1 0 0 0 0 2 1 1 0 1 0 1 0 1 1 1 1 1 1 0 0 0 0 0 0 0 0 0 1 0 1 0 2 2 0 1 0 2 1 0 0 0 0 0 2 3 1 1 0 0 0 0 0 1 1 0 0 0 1 0 0 0 0 0 1 0 0 2 1 0 0 0 1 0 0 0 0 0 0 0 1 0 0 0 0 1 1 0 0 2 0 2 0 0 0 0 0 0 0 0 0 0 0 1 0 0 0 0 0 0 1 0 1 0 0 1 0 1 0 0 0 0 0 0 1 0 0 0 0 1 0 0 0 0 0 1 0 0 0 2 0 0 0 0 2 0 0 0 0 0 0 1 0 0 0 0 0 0 0 0 1 1 0 0 0 1 1 0 1 1 1 0 0 0 0 2 0 0 0 0 0 0 0 0 0 0 0 0 0 0 0 1 0 0 0 0 0 1 0 0 0 0 0 0</counts>
			</dataPoints>
		</scan>
		<scan status="Completed" appendNumber="0" scanAxis="2Theta" mode="Continuous">
			<header>
				<startTimeStamp>2023-05-09T17:41:52-04:00</startTimeStamp>
				<endTimeStamp>2023-05-09T17:56:58-04:00</endTimeStamp>
				<author>
					<name>User</name>
				</author>
				<source>
					<applicationSoftware version="7.1">Data Collector</applicationSoftware>
					<instrumentControlSoftware version="8.2  20201204">EMPYREAN</instrumentControlSoftware>
					<instrumentID>0000000011260721</instrumentID>
				</source>
			</header>
			<dataPoints>
				<positions axis="2Theta" unit="deg">
					<startPosition>76.9678851475935</startPosition>
					<endPosition>80.31515491881</endPosition>
				</positions>
				<positions axis="Omega" unit="deg">
					<commonPosition>20.9054600166009</commonPosition>
				</positions>
				<positions axis="Phi" unit="deg">
					<commonPosition>-92.99</commonPosition>
				</positions>
				<positions axis="Chi" unit="deg">
					<commonPosition>0</commonPosition>
				</positions>
				<positions axis="Z" unit="mm">
					<commonPosition>8.384</commonPosition>
				</positions>
				<commonCountingTime unit="seconds">0.974</commonCountingTime>
				<counts unit="counts">2 1 0 0 0 1 0 0 0 0 1 2 1 0 1 1 0 0 1 1 0 1 1 0 1 0 1 0 0 1 1 0 1 1 0 0 0 0 0 0 0 1 0 0 0 0 1 0 0 2 1 0 0 2 0 1 0 2 0 2 0 0 0 0 0 1 0 0 2 2 0 1 1 0 0 0 0 1 0 0 2 0 0 0 0 0 0 1 0 1 1 2 1 0 1 1 0 0 1 0 0 0 0 0 0 0 1 0 0 0 0 0 0 0 0 0 2 0 0 1 2 0 0 0 0 1 0 0 0 0 0 0 0 0 0 1 0 1 0 1 0 3 0 0 0 0 0 0 0 1 0 0 0 0 0 0 1 0 0 1 1 0 2 0 2 1 0 1 1 0 0 0 0 0 0 0 1 0 0 0 0 2 1 0 0 0 0 0 1 0 2 0 1 0 0 0 0 0 0 0 0 0 0 1 0 0 1 1 0 0 0 0 0 0 0 1 1 3 0 0 0 0 0 0 0 0 0 0 0 1 1 0 0 0 0 0 0 0 0 0 0 0 0 0 0 0 0 0 0 0 0 0 0 0 0</counts>
			</dataPoints>
		</scan>
		<scan status="Completed" appendNumber="0" scanAxis="2Theta" mode="Continuous">
			<header>
				<startTimeStamp>2023-05-09T17:41:52-04:00</startTimeStamp>
				<endTimeStamp>2023-05-09T17:56:58-04:00</endTimeStamp>
				<author>
					<name>User</name>
				</author>
				<source>
					<applicationSoftware version="7.1">Data Collector</applicationSoftware>
					<instrumentControlSoftware version="8.2  20201204">EMPYREAN</instrumentControlSoftware>
					<instrumentID>0000000011260721</instrumentID>
				</source>
			</header>
			<dataPoints>
				<positions axis="2Theta" unit="deg">
					<startPosition>76.9711677182734</startPosition>
					<endPosition>80.3184374894898</endPosition>
				</positions>
				<positions axis="Omega" unit="deg">
					<commonPosition>20.9071013019408</commonPosition>
				</positions>
				<positions axis="Phi" unit="deg">
					<commonPosition>-92.99</commonPosition>
				</positions>
				<positions axis="Chi" unit="deg">
					<commonPosition>0</commonPosition>
				</positions>
				<positions axis="Z" unit="mm">
					<commonPosition>8.384</commonPosition>
				</positions>
				<commonCountingTime unit="seconds">0.974</commonCountingTime>
				<counts unit="counts">0 2 0 0 0 0 0 0 0 0 0 0 2 1 1 0 0 0 1 3 0 0 0 1 0 0 0 0 3 0 1 0 0 1 0 0 0 0 0 0 2 0 0 3 0 0 1 0 1 0 0 0 1 0 0 0 0 0 0 0 0 0 1 1 0 0 0 1 1 0 0 0 0 1 2 0 0 0 0 1 0 0 0 0 1 0 0 0 1 1 1 1 3 0 1 0 0 0 0 0 1 0 0 0 1 0 1 0 0 1 0 1 0 0 0 0 0 0 0 1 0 0 1 0 0 1 0 1 1 0 0 0 0 0 0 0 0 0 1 1 2 0 2 0 0 0 1 0 0 0 0 0 1 0 0 1 2 1 0 1 1 1 1 0 1 0 1 0 1 0 1 0 1 1 0 1 0 1 1 0 0 1 0 0 0 1 0 0 0 0 0 0 0 0 0 0 0 1 0 0 0 0 0 0 1 0 0 1 0 0 0 1 0 0 0 0 0 1 1 1 0 0 0 0 1 0 1 1 0 0 0 1 0 0 0 0 0 0 0 0 0 1 0 0 0 0 0 0 1 0 0 0 0 0 0</counts>
			</dataPoints>
		</scan>
		<scan status="Completed" appendNumber="0" scanAxis="2Theta" mode="Continuous">
			<header>
				<startTimeStamp>2023-05-09T17:41:52-04:00</startTimeStamp>
				<endTimeStamp>2023-05-09T17:56:58-04:00</endTimeStamp>
				<author>
					<name>User</name>
				</author>
				<source>
					<applicationSoftware version="7.1">Data Collector</applicationSoftware>
					<instrumentControlSoftware version="8.2  20201204">EMPYREAN</instrumentControlSoftware>
					<instrumentID>0000000011260721</instrumentID>
				</source>
			</header>
			<dataPoints>
				<positions axis="2Theta" unit="deg">
					<startPosition>76.9744502889532</startPosition>
					<endPosition>80.3217200601696</endPosition>
				</positions>
				<positions axis="Omega" unit="deg">
					<commonPosition>20.9087425872807</commonPosition>
				</positions>
				<positions axis="Phi" unit="deg">
					<commonPosition>-92.99</commonPosition>
				</positions>
				<positions axis="Chi" unit="deg">
					<commonPosition>0</commonPosition>
				</positions>
				<positions axis="Z" unit="mm">
					<commonPosition>8.384</commonPosition>
				</positions>
				<commonCountingTime unit="seconds">0.974</commonCountingTime>
				<counts unit="counts">0 0 0 0 0 0 0 0 1 0 1 0 0 0 1 4 0 0 0 2 0 1 0 1 0 0 0 0 0 0 0 0 0 1 0 0 0 1 0 0 0 2 0 0 2 0 0 1 1 0 1 2 2 0 0 0 0 0 0 0 0 0 3 1 0 2 0 0 0 1 0 0 0 0 1 2 0 1 0 1 1 0 0 0 1 0 1 3 0 0 0 1 0 0 0 1 0 0 0 1 0 0 0 1 0 0 0 0 0 0 1 0 0 0 0 1 2 0 0 0 0 0 0 0 0 1 0 0 0 1 0 0 0 0 0 1 3 0 0 0 1 0 1 0 1 0 0 0 0 1 0 0 1 0 0 0 0 2 0 1 1 0 1 0 1 0 1 0 1 0 0 0 0 1 0 1 1 1 1 0 0 0 0 0 0 1 1 0 1 0 0 0 0 1 0 0 0 0 1 0 1 1 0 0 0 0 0 1 0 0 0 0 0 0 0 0 0 0 1 0 0 0 1 0 0 1 0 0 0 1 0 0 0 1 0 0 0 1 0 0 0 1 1 0 0 1 2 0 0 0 0 1 0 0 2</counts>
			</dataPoints>
		</scan>
		<scan status="Completed" appendNumber="0" scanAxis="2Theta" mode="Continuous">
			<header>
				<startTimeStamp>2023-05-09T17:41:52-04:00</startTimeStamp>
				<endTimeStamp>2023-05-09T17:56:58-04:00</endTimeStamp>
				<author>
					<name>User</name>
				</author>
				<source>
					<applicationSoftware version="7.1">Data Collector</applicationSoftware>
					<instrumentControlSoftware version="8.2  20201204">EMPYREAN</instrumentControlSoftware>
					<instrumentID>0000000011260721</instrumentID>
				</source>
			</header>
			<dataPoints>
				<positions axis="2Theta" unit="deg">
					<startPosition>76.977732859633</startPosition>
					<endPosition>80.3250026308495</endPosition>
				</positions>
				<positions axis="Omega" unit="deg">
					<commonPosition>20.9103838726206</commonPosition>
				</positions>
				<positions axis="Phi" unit="deg">
					<commonPosition>-92.99</commonPosition>
				</positions>
				<positions axis="Chi" unit="deg">
					<commonPosition>0</commonPosition>
				</positions>
				<positions axis="Z" unit="mm">
					<commonPosition>8.384</commonPosition>
				</positions>
				<commonCountingTime unit="seconds">0.974</commonCountingTime>
				<counts unit="counts">0 0 0 0 0 0 0 0 0 1 0 1 0 1 0 1 0 0 0 0 1 1 0 1 2 1 0 0 1 0 1 0 0 1 1 0 0 0 0 0 0 0 0 0 0 1 0 0 0 0 0 1 1 1 0 1 0 1 1 0 1 0 0 1 0 0 0 1 2 1 0 1 0 0 1 1 0 1 0 0 0 0 1 0 0 0 0 0 0 0 1 0 2 2 1 1 3 0 1 0 0 3 1 2 0 0 0 0 1 2 0 0 1 0 0 1 2 0 0 0 0 0 0 0 0 0 0 0 0 0 1 0 0 0 0 0 0 0 0 0 0 0 0 0 0 0 0 0 0 1 0 0 1 1 0 0 0 0 0 0 0 0 0 1 0 0 0 0 0 0 0 0 0 0 0 1 1 0 0 0 0 0 0 0 1 0 0 0 0 0 1 0 0 0 0 0 0 1 0 0 0 0 0 0 0 0 0 1 1 0 0 1 0 1 0 0 0 0 0 0 0 1 0 2 0 0 0 1 1 0 0 1 0 0 1 0 0 0 0 0 0 0 0 0 0 0 0 0 0 0 0 1 0 0 0</counts>
			</dataPoints>
		</scan>
		<scan status="Completed" appendNumber="0" scanAxis="2Theta" mode="Continuous">
			<header>
				<startTimeStamp>2023-05-09T17:41:52-04:00</startTimeStamp>
				<endTimeStamp>2023-05-09T17:56:58-04:00</endTimeStamp>
				<author>
					<name>User</name>
				</author>
				<source>
					<applicationSoftware version="7.1">Data Collector</applicationSoftware>
					<instrumentControlSoftware version="8.2  20201204">EMPYREAN</instrumentControlSoftware>
					<instrumentID>0000000011260721</instrumentID>
				</source>
			</header>
			<dataPoints>
				<positions axis="2Theta" unit="deg">
					<startPosition>76.9810154303128</startPosition>
					<endPosition>80.3282852015293</endPosition>
				</positions>
				<positions axis="Omega" unit="deg">
					<commonPosition>20.9120251579605</commonPosition>
				</positions>
				<positions axis="Phi" unit="deg">
					<commonPosition>-92.99</commonPosition>
				</positions>
				<positions axis="Chi" unit="deg">
					<commonPosition>0</commonPosition>
				</positions>
				<positions axis="Z" unit="mm">
					<commonPosition>8.384</commonPosition>
				</positions>
				<commonCountingTime unit="seconds">0.974</commonCountingTime>
				<counts unit="counts">0 0 0 0 0 0 0 1 1 0 0 0 0 0 0 0 1 3 0 0 0 0 1 0 1 0 1 0 1 1 0 1 0 0 0 1 0 0 1 0 0 0 1 2 1 0 1 2 0 0 1 0 0 0 0 0 0 0 0 0 0 0 0 1 0 2 1 0 0 1 0 0 1 1 0 1 0 1 0 0 0 0 0 0 1 0 0 0 0 1 1 0 0 0 0 1 2 0 0 0 0 0 1 1 1 0 1 2 0 0 0 0 0 0 0 0 0 0 2 0 0 1 0 0 1 0 0 0 0 0 1 1 0 0 0 0 1 1 0 0 0 1 0 1 0 0 0 0 0 1 1 0 0 1 0 0 0 0 1 1 1 0 0 0 0 0 0 0 1 0 0 0 0 0 0 1 0 0 0 2 0 0 0 0 0 0 0 0 2 1 0 0 0 0 0 0 1 0 0 1 0 1 0 0 0 0 0 0 0 0 0 0 1 0 0 0 0 0 0 0 0 0 0 1 0 0 1 1 0 0 0 0 0 0 0 0 0 0 0 0 0 0 1 1 0 0 1 0 0 1 0 0 0 0 0</counts>
			</dataPoints>
		</scan>
		<scan status="Completed" appendNumber="0" scanAxis="2Theta" mode="Continuous">
			<header>
				<startTimeStamp>2023-05-09T17:41:52-04:00</startTimeStamp>
				<endTimeStamp>2023-05-09T17:56:58-04:00</endTimeStamp>
				<author>
					<name>User</name>
				</author>
				<source>
					<applicationSoftware version="7.1">Data Collector</applicationSoftware>
					<instrumentControlSoftware version="8.2  20201204">EMPYREAN</instrumentControlSoftware>
					<instrumentID>0000000011260721</instrumentID>
				</source>
			</header>
			<dataPoints>
				<positions axis="2Theta" unit="deg">
					<startPosition>76.9842980009927</startPosition>
					<endPosition>80.3315677722091</endPosition>
				</positions>
				<positions axis="Omega" unit="deg">
					<commonPosition>20.9136664433004</commonPosition>
				</positions>
				<positions axis="Phi" unit="deg">
					<commonPosition>-92.99</commonPosition>
				</positions>
				<positions axis="Chi" unit="deg">
					<commonPosition>0</commonPosition>
				</positions>
				<positions axis="Z" unit="mm">
					<commonPosition>8.384</commonPosition>
				</positions>
				<commonCountingTime unit="seconds">0.974</commonCountingTime>
				<counts unit="counts">0 0 0 2 1 0 0 0 0 2 0 0 0 0 0 0 0 0 1 0 0 0 0 0 0 1 2 0 1 1 0 1 0 0 0 1 0 1 0 0 1 0 0 1 0 0 1 1 0 0 0 1 3 0 2 0 0 3 0 0 0 1 0 0 2 0 1 0 0 0 0 0 0 1 1 0 0 0 0 0 0 0 0 0 0 0 0 0 0 0 0 0 1 0 0 0 2 0 0 0 0 0 0 0 0 0 0 0 0 0 0 0 0 0 0 0 1 0 0 0 0 1 0 0 0 0 0 0 0 1 0 0 0 1 1 1 0 0 1 0 0 0 0 0 1 0 0 0 0 1 0 0 0 0 0 0 0 0 0 0 0 0 0 2 0 0 0 1 1 1 0 0 0 0 0 0 0 0 1 0 0 0 0 0 1 0 0 0 1 0 1 0 0 0 0 0 0 0 0 0 0 0 0 1 0 0 0 0 0 0 0 0 1 0 0 0 0 0 0 0 1 1 0 1 0 1 1 0 2 0 0 0 0 0 0 0 0 0 0 0 0 1 1 0 0 0 0 0 0 0 0 0 0 0 2</counts>
			</dataPoints>
		</scan>
		<scan status="Completed" appendNumber="0" scanAxis="2Theta" mode="Continuous">
			<header>
				<startTimeStamp>2023-05-09T17:41:52-04:00</startTimeStamp>
				<endTimeStamp>2023-05-09T17:56:58-04:00</endTimeStamp>
				<author>
					<name>User</name>
				</author>
				<source>
					<applicationSoftware version="7.1">Data Collector</applicationSoftware>
					<instrumentControlSoftware version="8.2  20201204">EMPYREAN</instrumentControlSoftware>
					<instrumentID>0000000011260721</instrumentID>
				</source>
			</header>
			<dataPoints>
				<positions axis="2Theta" unit="deg">
					<startPosition>76.9875805716725</startPosition>
					<endPosition>80.334850342889</endPosition>
				</positions>
				<positions axis="Omega" unit="deg">
					<commonPosition>20.9153077286404</commonPosition>
				</positions>
				<positions axis="Phi" unit="deg">
					<commonPosition>-92.99</commonPosition>
				</positions>
				<positions axis="Chi" unit="deg">
					<commonPosition>0</commonPosition>
				</positions>
				<positions axis="Z" unit="mm">
					<commonPosition>8.384</commonPosition>
				</positions>
				<commonCountingTime unit="seconds">0.974</commonCountingTime>
				<counts unit="counts">0 0 1 0 1 2 0 0 1 0 1 0 2 0 2 0 0 1 1 0 0 1 0 0 0 1 0 0 0 0 1 1 0 0 0 1 0 0 0 0 0 0 0 0 0 0 0 0 1 0 1 0 0 0 0 3 1 0 0 2 2 0 0 0 0 0 1 0 1 1 0 0 0 0 0 1 0 1 0 0 0 0 0 1 0 1 0 0 1 1 0 0 0 0 0 2 0 0 0 0 0 0 0 0 0 0 0 0 0 0 0 0 0 2 1 1 0 0 0 2 0 0 0 1 0 0 0 1 0 1 0 0 0 0 0 0 0 0 0 1 0 1 1 0 1 0 0 0 0 0 0 0 0 0 0 1 0 0 1 0 1 0 0 0 0 0 0 1 0 0 0 0 0 0 1 1 0 0 0 0 2 1 0 0 0 1 1 1 0 0 0 0 0 0 0 0 1 0 0 0 1 0 0 0 1 1 0 1 0 0 0 0 0 1 0 0 0 0 0 0 1 0 0 0 0 1 0 0 0 0 0 0 0 0 0 0 1 0 1 0 0 0 1 0 0 0 0 0 0 1 1 0 0 0 1</counts>
			</dataPoints>
		</scan>
		<scan status="Completed" appendNumber="0" scanAxis="2Theta" mode="Continuous">
			<header>
				<startTimeStamp>2023-05-09T17:41:52-04:00</startTimeStamp>
				<endTimeStamp>2023-05-09T17:56:58-04:00</endTimeStamp>
				<author>
					<name>User</name>
				</author>
				<source>
					<applicationSoftware version="7.1">Data Collector</applicationSoftware>
					<instrumentControlSoftware version="8.2  20201204">EMPYREAN</instrumentControlSoftware>
					<instrumentID>0000000011260721</instrumentID>
				</source>
			</header>
			<dataPoints>
				<positions axis="2Theta" unit="deg">
					<startPosition>76.9908631423523</startPosition>
					<endPosition>80.3381329135688</endPosition>
				</positions>
				<positions axis="Omega" unit="deg">
					<commonPosition>20.9169490139803</commonPosition>
				</positions>
				<positions axis="Phi" unit="deg">
					<commonPosition>-92.99</commonPosition>
				</positions>
				<positions axis="Chi" unit="deg">
					<commonPosition>0</commonPosition>
				</positions>
				<positions axis="Z" unit="mm">
					<commonPosition>8.384</commonPosition>
				</positions>
				<commonCountingTime unit="seconds">0.974</commonCountingTime>
				<counts unit="counts">0 0 0 0 0 0 0 0 1 1 0 0 1 0 2 0 4 0 0 0 1 1 0 0 0 0 1 1 0 1 1 0 0 0 0 0 1 0 0 0 1 1 2 0 1 1 1 0 2 0 0 0 1 0 0 0 0 1 0 0 0 0 0 0 0 1 0 1 1 0 1 0 1 3 0 0 0 0 2 0 0 0 0 0 0 0 0 0 0 1 0 0 0 0 1 0 0 0 0 1 1 0 0 1 1 0 0 0 0 1 1 1 0 0 0 0 0 0 0 0 1 0 0 1 0 0 1 0 1 0 0 0 0 0 0 1 0 0 0 0 0 1 0 0 0 1 1 0 1 0 0 1 0 0 0 2 1 0 0 0 0 0 0 0 0 0 0 0 0 0 0 1 0 0 0 0 0 1 1 0 0 0 0 0 0 0 0 1 0 1 0 1 0 2 0 1 1 0 1 0 1 0 1 1 0 0 0 2 1 1 0 0 0 0 0 1 0 0 0 0 1 0 0 0 0 0 0 0 0 0 2 1 0 0 1 0 0 0 1 0 0 0 1 1 0 0 0 0 0 0 0 0 0 1 0</counts>
			</dataPoints>
		</scan>
		<scan status="Completed" appendNumber="0" scanAxis="2Theta" mode="Continuous">
			<header>
				<startTimeStamp>2023-05-09T17:41:52-04:00</startTimeStamp>
				<endTimeStamp>2023-05-09T17:56:58-04:00</endTimeStamp>
				<author>
					<name>User</name>
				</author>
				<source>
					<applicationSoftware version="7.1">Data Collector</applicationSoftware>
					<instrumentControlSoftware version="8.2  20201204">EMPYREAN</instrumentControlSoftware>
					<instrumentID>0000000011260721</instrumentID>
				</source>
			</header>
			<dataPoints>
				<positions axis="2Theta" unit="deg">
					<startPosition>76.9941457130321</startPosition>
					<endPosition>80.3414154842486</endPosition>
				</positions>
				<positions axis="Omega" unit="deg">
					<commonPosition>20.9185902993202</commonPosition>
				</positions>
				<positions axis="Phi" unit="deg">
					<commonPosition>-92.99</commonPosition>
				</positions>
				<positions axis="Chi" unit="deg">
					<commonPosition>0</commonPosition>
				</positions>
				<positions axis="Z" unit="mm">
					<commonPosition>8.384</commonPosition>
				</positions>
				<commonCountingTime unit="seconds">0.974</commonCountingTime>
				<counts unit="counts">0 0 0 0 0 1 0 0 0 1 1 1 1 0 0 0 0 1 1 1 0 0 0 0 1 0 1 0 1 1 0 0 0 2 0 0 0 0 2 3 1 1 0 0 0 0 1 0 1 0 0 0 0 0 2 1 1 1 0 0 1 2 0 0 1 0 1 1 0 1 0 0 0 1 0 0 1 1 0 0 1 0 0 0 0 0 0 1 2 0 1 1 1 2 2 0 0 0 1 0 2 1 0 0 1 0 0 1 1 0 0 0 1 0 0 0 1 0 0 0 0 1 0 1 0 1 0 0 1 1 0 1 0 1 1 0 0 0 0 0 0 0 0 0 0 0 0 1 0 2 0 1 0 0 0 0 0 0 0 0 0 0 1 0 0 0 1 0 0 1 0 0 0 0 1 0 0 0 0 0 0 0 0 0 0 0 0 1 0 0 0 0 0 0 0 0 0 0 0 0 1 0 1 0 0 0 0 0 0 0 1 0 2 0 0 0 0 0 0 0 0 0 0 2 1 0 0 0 0 1 0 0 0 0 1 0 0 0 0 0 0 0 0 0 1 0 0 0 0 0 1 1 0 0 0</counts>
			</dataPoints>
		</scan>
		<scan status="Completed" appendNumber="0" scanAxis="2Theta" mode="Continuous">
			<header>
				<startTimeStamp>2023-05-09T17:41:52-04:00</startTimeStamp>
				<endTimeStamp>2023-05-09T17:56:58-04:00</endTimeStamp>
				<author>
					<name>User</name>
				</author>
				<source>
					<applicationSoftware version="7.1">Data Collector</applicationSoftware>
					<instrumentControlSoftware version="8.2  20201204">EMPYREAN</instrumentControlSoftware>
					<instrumentID>0000000011260721</instrumentID>
				</source>
			</header>
			<dataPoints>
				<positions axis="2Theta" unit="deg">
					<startPosition>76.9974282837119</startPosition>
					<endPosition>80.3446980549284</endPosition>
				</positions>
				<positions axis="Omega" unit="deg">
					<commonPosition>20.9202315846601</commonPosition>
				</positions>
				<positions axis="Phi" unit="deg">
					<commonPosition>-92.99</commonPosition>
				</positions>
				<positions axis="Chi" unit="deg">
					<commonPosition>0</commonPosition>
				</positions>
				<positions axis="Z" unit="mm">
					<commonPosition>8.384</commonPosition>
				</positions>
				<commonCountingTime unit="seconds">0.974</commonCountingTime>
				<counts unit="counts">0 0 3 1 1 1 1 1 1 0 0 2 1 1 0 2 0 1 0 0 0 1 0 1 0 0 1 0 0 0 0 0 0 0 0 2 0 0 0 0 0 1 1 0 0 0 0 1 0 0 1 0 0 1 0 1 0 1 1 0 2 0 0 1 0 0 0 0 0 0 0 0 0 0 0 0 0 1 1 1 0 1 0 0 0 0 0 0 0 0 1 1 0 1 2 1 2 0 0 0 0 0 0 0 0 2 2 0 0 0 0 0 0 0 0 0 0 0 0 0 1 0 1 0 0 0 0 0 1 0 0 0 0 1 0 0 0 0 1 0 1 0 0 0 0 2 0 0 0 0 0 0 0 0 0 0 0 0 0 0 0 0 0 0 0 0 0 0 0 1 0 0 1 0 0 0 0 0 0 0 0 0 0 0 1 0 1 1 0 0 1 2 0 0 2 0 1 0 1 0 1 0 3 2 1 1 0 0 1 1 0 0 0 0 1 0 2 0 1 0 0 0 1 0 0 1 0 0 0 0 0 0 0 0 0 0 0 0 0 0 0 0 0 0 1 0 0 0 0 0 0 1 0 0 0</counts>
			</dataPoints>
		</scan>
		<scan status="Completed" appendNumber="0" scanAxis="2Theta" mode="Continuous">
			<header>
				<startTimeStamp>2023-05-09T17:41:52-04:00</startTimeStamp>
				<endTimeStamp>2023-05-09T17:56:58-04:00</endTimeStamp>
				<author>
					<name>User</name>
				</author>
				<source>
					<applicationSoftware version="7.1">Data Collector</applicationSoftware>
					<instrumentControlSoftware version="8.2  20201204">EMPYREAN</instrumentControlSoftware>
					<instrumentID>0000000011260721</instrumentID>
				</source>
			</header>
			<dataPoints>
				<positions axis="2Theta" unit="deg">
					<startPosition>77.0007108543918</startPosition>
					<endPosition>80.3479806256082</endPosition>
				</positions>
				<positions axis="Omega" unit="deg">
					<commonPosition>20.92187287</commonPosition>
				</positions>
				<positions axis="Phi" unit="deg">
					<commonPosition>-92.99</commonPosition>
				</positions>
				<positions axis="Chi" unit="deg">
					<commonPosition>0</commonPosition>
				</positions>
				<positions axis="Z" unit="mm">
					<commonPosition>8.384</commonPosition>
				</positions>
				<commonCountingTime unit="seconds">0.974</commonCountingTime>
				<counts unit="counts">1 0 0 0 0 0 1 0 1 1 2 1 0 0 0 1 0 2 1 0 0 1 0 0 1 1 0 0 1 0 0 1 0 0 0 1 0 0 0 0 0 0 2 1 0 1 0 0 0 0 2 0 0 1 1 1 0 2 0 0 0 1 0 0 1 0 0 0 0 1 0 0 2 0 1 1 1 0 0 0 0 0 0 0 0 0 0 1 0 0 3 1 0 0 1 0 2 2 0 0 1 0 0 0 0 2 1 1 0 0 2 0 0 1 1 0 0 1 1 0 1 0 0 0 0 0 0 1 1 0 0 0 0 0 0 0 0 0 0 0 1 0 0 0 0 0 1 0 0 0 1 1 0 0 0 0 0 0 2 0 0 0 0 0 0 0 0 0 0 0 0 0 0 0 1 0 0 0 0 0 0 1 0 0 1 0 0 0 0 0 0 0 1 0 1 0 0 0 0 1 0 1 0 0 1 1 0 0 1 0 0 0 0 1 0 0 1 0 0 0 1 0 0 0 1 0 0 0 0 0 0 0 0 0 0 0 1 0 1 1 0 1 1 0 0 1 0 0 0 0 0 0 0 0 0</counts>
			</dataPoints>
		</scan>
	</xrdMeasurement>
</xrdMeasurements>