File: m3_learning/papers/2023_RHEED_PLD_SrTiO3/Data/XRD/treated_81nm-RSM_002.xrdml
<?xml version="1.0" encoding="utf-8"?>
<xrdMeasurements xmlns="http://www.xrdml.com/XRDMeasurement/2.2" xmlns:xsi="http://www.w3.org/2001/XMLSchema-instance" xsi:schemaLocation="http://www.xrdml.com/XRDMeasurement/2.2 http://www.xrdml.com/XRDMeasurement/2.2/XRDMeasurement.xsd" status="Completed">
	<comment>
		<entry>Configuration=3-axes Cradle_Reflection, Owner=User, Creation date=9/2/2021 3:55:24 PM</entry>
		<entry>Goniometer=Theta/Theta; Minimum step size 2Theta:0.0001; Minimum step size Omega:0.0001</entry>
		<entry>Sample stage=Chi-Phi-z stage 240 mm (reflection); Minimum step size Phi:0.01; Minimum step size Chi:0.01; Minimum step size Z:0.001</entry>
		<entry>Diffractometer system=EMPYREAN</entry>
		<entry>Measurement program=C:\PANalytical\Data Collector\Programs\Liyan Wu\Film programs\RSM slow 1.5 degree.xrdmp, Identifier={0A137119-D990-4D5D-A198-A9BB75A0EC1A}</entry>
	</comment>
	<sample type="To be analyzed">
		<id/>
		<name/>
		<preparedBy/>
	</sample>
	<xrdMeasurement status="Completed" measurementType="Area measurement" measurementStepAxis="Omega-2Theta" sampleMode="Reflection">
		<comment>
			<entry>PHD Lower Level = 4.02 (keV), PHD Upper Level = 11.26 (keV)</entry>
		</comment>
		<usedWavelength intended="K-Alpha">
			<kAlpha1 unit="Angstrom">1.5405980</kAlpha1>
			<kAlpha2 unit="Angstrom">1.5444260</kAlpha2>
			<kBeta unit="Angstrom">1.3922500</kBeta>
			<ratioKAlpha2KAlpha1>0</ratioKAlpha2KAlpha1>
		</usedWavelength>
		<incidentBeamPath>
			<radius unit="mm">240.00</radius>
			<xRayTube id="1010048" name="Empyrean Cu LFF HR (9430 033 7310x) DK432574">
				<tension unit="kV">45.0</tension>
				<current unit="mA">40.0</current>
				<anodeMaterial>Cu</anodeMaterial>
				<focus type="Line">
					<length unit="mm">12.0</length>
					<width unit="mm">0.4</width>
					<takeOffAngle unit="deg">4.4</takeOffAngle>
				</focus>
			</xRayTube>
			<xRayMirror xsi:type="xRayMirrorType" id="27080001" name="Inc. Beam Cu W/Si (hybrid MPD)" hybrid="true">
				<crystal type="Graded" shape="Parabolic">W/Si</crystal>
				<acceptanceAngle unit="deg">0.800</acceptanceAngle>
				<length unit="mm">55.3</length>
			</xRayMirror>
			<monochromator xsi:type="monochromatorType" id="23090002" name="Hybrid monochr. 2xGe220 Cu asym." hybrid="true">
				<crystal type="Asymmetric" shape="Flat">Ge</crystal>
				<numberOfReflections>2</numberOfReflections>
				<hkl>
					<h>2</h>
					<k>2</k>
					<l>0</l>
				</hkl>
			</monochromator>
			<divergenceSlit xsi:type="fixedDivergenceSlitType" id="22010005" name="Fixed slit 1/4°">
				<distanceToSample unit="mm">179.30</distanceToSample>
				<height unit="mm">0.38</height>
			</divergenceSlit>
		</incidentBeamPath>
		<diffractedBeamPath>
			<radius unit="mm">240.00</radius>
			<antiScatterSlit xsi:type="fixedAntiScatterSlitType" id="22060009" name="Programmable anti-scatter slit">
				<angle unit="deg">4</angle>
			</antiScatterSlit>
			<detector xsi:type="areaDetectorType" id="7010020" name="PIXcel3D-Medipix3 1x1 detector">
				<phd unit="%">
					<lowerLevel>25</lowerLevel>
					<upperLevel>70</upperLevel>
				</phd>
				<mode>Scanning snapshot equatorial</mode>
				<activeChannelsEquatorial>255</activeChannelsEquatorial>
				<activeChannelsAxial>255</activeChannelsAxial>
				<pitchEquatorial unit="mm">0.05500</pitchEquatorial>
				<pitchAxial unit="mm">0.05500</pitchAxial>
				<readOutPeriod unit="seconds">0.980</readOutPeriod>
			</detector>
		</diffractedBeamPath>
		<scan status="Completed" appendNumber="0" scanAxis="2Theta" mode="Continuous">
			<header>
				<startTimeStamp>2023-05-31T14:00:09-04:00</startTimeStamp>
				<endTimeStamp>2023-05-31T14:15:20-04:00</endTimeStamp>
				<author>
					<name>User</name>
				</author>
				<source>
					<applicationSoftware version="7.1">Data Collector</applicationSoftware>
					<instrumentControlSoftware version="8.2  20201204">EMPYREAN</instrumentControlSoftware>
					<instrumentID>0000000011260721</instrumentID>
				</source>
			</header>
			<dataPoints>
				<positions axis="2Theta" unit="deg">
					<startPosition>43.3424063943918</startPosition>
					<endPosition>46.6896761656082</endPosition>
				</positions>
				<positions axis="Omega" unit="deg">
					<commonPosition>22.50942064</commonPosition>
				</positions>
				<positions axis="Phi" unit="deg">
					<commonPosition>0</commonPosition>
				</positions>
				<positions axis="Chi" unit="deg">
					<commonPosition>-0.72</commonPosition>
				</positions>
				<positions axis="Z" unit="mm">
					<commonPosition>8.487</commonPosition>
				</positions>
				<commonCountingTime unit="seconds">0.974</commonCountingTime>
				<counts unit="counts">0 0 1 0 0 0 0 1 0 0 0 1 0 0 0 1 0 0 0 0 0 0 1 0 0 0 0 0 0 0 0 0 0 1 0 0 0 0 1 0 0 0 1 0 0 1 1 2 0 0 0 0 0 0 0 1 0 0 1 0 0 0 1 1 1 1 1 0 0 1 2 0 0 0 0 0 1 0 0 0 0 0 1 0 0 0 0 1 0 0 1 0 0 0 0 2 0 0 0 0 1 0 0 0 1 0 0 0 1 0 0 0 0 1 0 0 0 0 0 1 0 0 1 0 0 1 1 1 4 1 1 0 1 0 1 0 0 0 0 0 0 1 0 2 0 1 0 0 1 0 0 0 0 0 0 0 3 0 0 0 0 0 0 0 1 0 0 0 0 0 0 0 0 0 1 0 0 0 0 1 0 0 0 0 0 0 0 0 0 1 1 0 0 2 0 0 0 2 1 0 1 1 0 1 1 0 0 0 0 0 1 0 1 0 0 1 0 0 0 2 0 0 0 0 0 0 1 0 0 1 1 1 1 2 3 4 4 1 6 9 2 5 7 3 2 0 1 0 0 1 0 0 1 0 1</counts>
			</dataPoints>
		</scan>
		<scan status="Completed" appendNumber="0" scanAxis="2Theta" mode="Continuous">
			<header>
				<startTimeStamp>2023-05-31T14:00:09-04:00</startTimeStamp>
				<endTimeStamp>2023-05-31T14:15:20-04:00</endTimeStamp>
				<author>
					<name>User</name>
				</author>
				<source>
					<applicationSoftware version="7.1">Data Collector</applicationSoftware>
					<instrumentControlSoftware version="8.2  20201204">EMPYREAN</instrumentControlSoftware>
					<instrumentID>0000000011260721</instrumentID>
				</source>
			</header>
			<dataPoints>
				<positions axis="2Theta" unit="deg">
					<startPosition>43.3456889650716</startPosition>
					<endPosition>46.6929587362881</endPosition>
				</positions>
				<positions axis="Omega" unit="deg">
					<commonPosition>22.5110619253399</commonPosition>
				</positions>
				<positions axis="Phi" unit="deg">
					<commonPosition>0</commonPosition>
				</positions>
				<positions axis="Chi" unit="deg">
					<commonPosition>-0.72</commonPosition>
				</positions>
				<positions axis="Z" unit="mm">
					<commonPosition>8.487</commonPosition>
				</positions>
				<commonCountingTime unit="seconds">0.974</commonCountingTime>
				<counts unit="counts">0 1 0 1 0 1 0 1 1 0 0 0 0 0 0 0 0 0 0 0 0 0 1 1 0 0 0 0 0 0 0 0 0 0 0 0 1 0 0 0 0 0 1 1 0 0 0 0 0 1 0 1 0 0 0 0 0 1 0 0 0 0 1 0 1 0 1 0 0 0 0 1 0 0 1 0 0 0 0 0 0 2 1 0 0 0 1 1 0 0 0 1 0 0 2 0 0 0 0 1 0 0 0 0 1 0 0 1 0 0 0 0 0 1 1 0 0 0 1 0 0 0 1 1 0 1 1 2 3 0 0 1 0 1 1 0 0 0 0 0 0 2 0 0 1 1 0 0 0 0 0 1 0 0 0 2 1 0 1 0 1 0 3 1 0 0 0 0 0 1 0 0 1 0 2 0 0 0 1 0 1 0 0 1 0 0 0 2 1 0 1 0 0 0 0 0 0 0 0 0 0 0 0 0 1 0 0 0 0 2 0 0 0 1 1 0 0 0 1 0 0 1 0 1 0 1 0 1 1 1 0 0 1 0 3 3 2 3 6 1 2 2 3 1 2 1 0 2 0 0 1 0 0 0 2</counts>
			</dataPoints>
		</scan>
		<scan status="Completed" appendNumber="0" scanAxis="2Theta" mode="Continuous">
			<header>
				<startTimeStamp>2023-05-31T14:00:09-04:00</startTimeStamp>
				<endTimeStamp>2023-05-31T14:15:20-04:00</endTimeStamp>
				<author>
					<name>User</name>
				</author>
				<source>
					<applicationSoftware version="7.1">Data Collector</applicationSoftware>
					<instrumentControlSoftware version="8.2  20201204">EMPYREAN</instrumentControlSoftware>
					<instrumentID>0000000011260721</instrumentID>
				</source>
			</header>
			<dataPoints>
				<positions axis="2Theta" unit="deg">
					<startPosition>43.3489715357514</startPosition>
					<endPosition>46.6962413069679</endPosition>
				</positions>
				<positions axis="Omega" unit="deg">
					<commonPosition>22.5127032106798</commonPosition>
				</positions>
				<positions axis="Phi" unit="deg">
					<commonPosition>0</commonPosition>
				</positions>
				<positions axis="Chi" unit="deg">
					<commonPosition>-0.72</commonPosition>
				</positions>
				<positions axis="Z" unit="mm">
					<commonPosition>8.487</commonPosition>
				</positions>
				<commonCountingTime unit="seconds">0.974</commonCountingTime>
				<counts unit="counts">0 1 3 1 0 0 1 2 0 0 0 0 0 0 1 0 0 0 0 0 0 0 1 0 1 0 0 0 0 2 0 0 0 0 0 0 0 1 1 0 0 1 0 0 0 0 0 0 0 0 0 0 1 1 0 1 0 0 0 0 1 0 0 0 0 0 0 0 1 0 0 1 0 1 0 0 1 0 0 0 1 0 0 0 1 0 0 0 1 0 0 2 0 0 0 0 0 0 2 0 0 0 1 0 0 0 0 1 1 2 0 1 0 1 1 0 1 0 0 0 1 1 0 0 1 0 3 1 0 0 0 0 0 0 0 0 1 0 1 0 1 0 0 0 0 0 0 0 0 0 0 0 1 0 0 0 0 0 0 0 1 1 0 0 1 0 1 0 1 0 0 1 0 0 0 1 1 0 0 0 0 0 1 0 0 0 1 0 1 0 1 1 1 1 1 1 2 1 1 0 1 1 0 0 1 1 0 0 2 5 0 0 0 0 0 1 2 0 1 0 1 0 1 3 0 1 2 0 1 0 0 2 3 3 2 4 2 6 6 2 4 3 0 1 1 1 1 0 0 1 1 0 0 1 0</counts>
			</dataPoints>
		</scan>
		<scan status="Completed" appendNumber="0" scanAxis="2Theta" mode="Continuous">
			<header>
				<startTimeStamp>2023-05-31T14:00:09-04:00</startTimeStamp>
				<endTimeStamp>2023-05-31T14:15:20-04:00</endTimeStamp>
				<author>
					<name>User</name>
				</author>
				<source>
					<applicationSoftware version="7.1">Data Collector</applicationSoftware>
					<instrumentControlSoftware version="8.2  20201204">EMPYREAN</instrumentControlSoftware>
					<instrumentID>0000000011260721</instrumentID>
				</source>
			</header>
			<dataPoints>
				<positions axis="2Theta" unit="deg">
					<startPosition>43.3522541064312</startPosition>
					<endPosition>46.6995238776477</endPosition>
				</positions>
				<positions axis="Omega" unit="deg">
					<commonPosition>22.5143444960197</commonPosition>
				</positions>
				<positions axis="Phi" unit="deg">
					<commonPosition>0</commonPosition>
				</positions>
				<positions axis="Chi" unit="deg">
					<commonPosition>-0.72</commonPosition>
				</positions>
				<positions axis="Z" unit="mm">
					<commonPosition>8.487</commonPosition>
				</positions>
				<commonCountingTime unit="seconds">0.974</commonCountingTime>
				<counts unit="counts">0 1 1 0 0 0 0 1 0 0 0 0 0 0 1 0 0 0 0 0 1 0 0 0 0 0 0 0 0 0 0 0 0 1 0 1 0 0 0 1 0 1 0 0 1 0 1 0 0 1 1 1 0 1 0 0 0 0 0 0 1 0 0 0 0 0 0 0 1 0 0 0 0 0 1 0 0 1 0 1 1 0 1 1 0 0 1 1 0 0 1 0 1 0 0 0 1 0 0 0 0 1 0 1 0 0 2 0 0 0 2 1 1 0 0 0 0 1 0 0 2 0 1 0 0 1 1 0 3 0 0 0 0 0 1 1 0 0 0 0 2 0 3 1 0 1 0 0 1 0 0 0 0 0 0 0 0 0 0 2 1 0 0 0 0 1 0 0 1 0 1 0 0 0 0 0 0 0 0 0 0 0 1 1 0 0 0 0 1 0 0 0 0 0 1 1 0 0 1 1 3 2 0 0 1 0 1 2 1 0 1 0 0 1 1 0 0 0 0 1 2 0 0 1 1 1 0 1 0 1 2 1 3 1 0 3 2 9 4 2 3 4 6 1 1 1 1 2 1 1 0 3 1 0 1</counts>
			</dataPoints>
		</scan>
		<scan status="Completed" appendNumber="0" scanAxis="2Theta" mode="Continuous">
			<header>
				<startTimeStamp>2023-05-31T14:00:09-04:00</startTimeStamp>
				<endTimeStamp>2023-05-31T14:15:20-04:00</endTimeStamp>
				<author>
					<name>User</name>
				</author>
				<source>
					<applicationSoftware version="7.1">Data Collector</applicationSoftware>
					<instrumentControlSoftware version="8.2  20201204">EMPYREAN</instrumentControlSoftware>
					<instrumentID>0000000011260721</instrumentID>
				</source>
			</header>
			<dataPoints>
				<positions axis="2Theta" unit="deg">
					<startPosition>43.3555366771111</startPosition>
					<endPosition>46.7028064483275</endPosition>
				</positions>
				<positions axis="Omega" unit="deg">
					<commonPosition>22.5159857813596</commonPosition>
				</positions>
				<positions axis="Phi" unit="deg">
					<commonPosition>0</commonPosition>
				</positions>
				<positions axis="Chi" unit="deg">
					<commonPosition>-0.72</commonPosition>
				</positions>
				<positions axis="Z" unit="mm">
					<commonPosition>8.487</commonPosition>
				</positions>
				<commonCountingTime unit="seconds">0.974</commonCountingTime>
				<counts unit="counts">0 0 0 0 0 0 2 0 1 0 0 0 1 0 0 1 2 0 0 1 1 1 0 1 0 0 0 0 1 1 0 0 0 0 0 0 1 2 0 0 0 0 0 0 1 0 0 1 0 0 0 0 0 1 2 1 0 0 0 0 0 0 0 0 0 1 0 0 0 0 0 0 0 0 0 0 0 0 1 0 0 0 0 3 0 0 0 0 0 0 0 0 0 0 0 0 0 1 0 0 0 0 0 0 1 0 1 1 0 1 0 0 0 0 0 0 0 1 0 0 1 0 1 0 1 0 1 3 5 0 1 0 0 0 0 0 1 0 0 0 2 0 1 0 0 0 1 1 0 0 0 0 1 1 0 0 0 0 0 1 0 0 1 1 1 0 1 0 1 0 1 0 1 0 1 0 0 1 0 0 1 2 0 2 0 1 0 1 0 0 1 0 0 0 1 2 1 0 1 0 0 0 1 3 0 1 0 0 0 0 0 0 0 0 0 1 0 0 0 0 1 0 2 1 0 0 0 0 0 2 3 1 2 2 2 3 8 4 5 9 2 4 0 0 0 0 1 0 1 1 3 2 0 0 0</counts>
			</dataPoints>
		</scan>
		<scan status="Completed" appendNumber="0" scanAxis="2Theta" mode="Continuous">
			<header>
				<startTimeStamp>2023-05-31T14:00:09-04:00</startTimeStamp>
				<endTimeStamp>2023-05-31T14:15:20-04:00</endTimeStamp>
				<author>
					<name>User</name>
				</author>
				<source>
					<applicationSoftware version="7.1">Data Collector</applicationSoftware>
					<instrumentControlSoftware version="8.2  20201204">EMPYREAN</instrumentControlSoftware>
					<instrumentID>0000000011260721</instrumentID>
				</source>
			</header>
			<dataPoints>
				<positions axis="2Theta" unit="deg">
					<startPosition>43.3588192477909</startPosition>
					<endPosition>46.7060890190074</endPosition>
				</positions>
				<positions axis="Omega" unit="deg">
					<commonPosition>22.5176270666996</commonPosition>
				</positions>
				<positions axis="Phi" unit="deg">
					<commonPosition>0</commonPosition>
				</positions>
				<positions axis="Chi" unit="deg">
					<commonPosition>-0.72</commonPosition>
				</positions>
				<positions axis="Z" unit="mm">
					<commonPosition>8.487</commonPosition>
				</positions>
				<commonCountingTime unit="seconds">0.974</commonCountingTime>
				<counts unit="counts">0 1 0 1 0 1 0 0 1 0 2 0 1 0 0 1 0 0 0 0 0 0 2 0 0 0 0 0 1 0 2 1 0 0 0 0 0 0 0 0 0 0 0 0 0 0 0 0 0 0 0 0 3 0 0 1 0 0 0 0 0 0 0 0 0 1 1 0 1 0 0 1 0 1 0 0 0 0 0 0 0 0 1 0 0 0 0 0 0 0 2 0 0 0 0 1 0 1 0 2 0 0 0 0 1 1 0 1 0 0 0 0 1 0 0 0 0 1 0 0 0 0 1 0 0 1 0 1 0 1 0 1 2 1 0 0 0 2 0 0 0 0 0 0 0 0 0 1 0 0 1 2 0 0 1 0 0 0 1 0 1 0 0 0 1 0 1 0 1 0 1 0 0 2 0 0 0 0 0 0 0 1 0 0 1 0 0 0 0 0 1 0 1 1 0 1 1 0 0 0 1 3 1 1 0 1 0 2 1 0 1 1 0 0 0 2 1 1 1 0 3 0 0 0 1 1 0 0 1 1 1 0 3 3 3 1 6 6 1 3 1 4 0 1 1 0 1 1 0 0 0 0 0 2 1</counts>
			</dataPoints>
		</scan>
		<scan status="Completed" appendNumber="0" scanAxis="2Theta" mode="Continuous">
			<header>
				<startTimeStamp>2023-05-31T14:00:09-04:00</startTimeStamp>
				<endTimeStamp>2023-05-31T14:15:20-04:00</endTimeStamp>
				<author>
					<name>User</name>
				</author>
				<source>
					<applicationSoftware version="7.1">Data Collector</applicationSoftware>
					<instrumentControlSoftware version="8.2  20201204">EMPYREAN</instrumentControlSoftware>
					<instrumentID>0000000011260721</instrumentID>
				</source>
			</header>
			<dataPoints>
				<positions axis="2Theta" unit="deg">
					<startPosition>43.3621018184707</startPosition>
					<endPosition>46.7093715896872</endPosition>
				</positions>
				<positions axis="Omega" unit="deg">
					<commonPosition>22.5192683520395</commonPosition>
				</positions>
				<positions axis="Phi" unit="deg">
					<commonPosition>0</commonPosition>
				</positions>
				<positions axis="Chi" unit="deg">
					<commonPosition>-0.72</commonPosition>
				</positions>
				<positions axis="Z" unit="mm">
					<commonPosition>8.487</commonPosition>
				</positions>
				<commonCountingTime unit="seconds">0.974</commonCountingTime>
				<counts unit="counts">0 0 1 0 0 0 0 0 0 0 0 1 0 0 0 0 0 0 0 0 0 0 0 0 0 0 0 0 2 0 0 0 0 0 0 1 0 0 1 0 0 0 0 2 0 1 0 0 0 0 0 0 1 0 0 0 1 0 0 2 0 1 0 0 0 0 0 0 1 0 3 1 0 0 1 0 2 0 1 0 0 0 0 0 0 1 0 0 1 0 1 0 0 0 0 0 0 0 0 1 1 1 0 0 0 0 0 1 0 0 0 2 0 1 0 0 0 1 0 0 0 0 0 0 1 0 0 2 1 0 0 0 1 1 2 0 0 0 0 1 1 0 1 0 0 0 0 1 1 0 0 0 0 1 0 0 0 0 0 3 0 1 0 0 1 1 0 0 1 0 2 0 0 0 0 0 0 1 0 0 1 0 1 0 0 0 0 0 0 0 2 0 0 1 0 0 1 0 0 0 0 0 0 0 1 0 0 1 0 0 0 1 0 0 0 0 1 0 2 3 0 1 0 3 0 1 0 2 0 1 2 3 0 1 2 4 3 6 3 4 3 0 3 2 1 1 3 0 0 2 0 1 1 0 0</counts>
			</dataPoints>
		</scan>
		<scan status="Completed" appendNumber="0" scanAxis="2Theta" mode="Continuous">
			<header>
				<startTimeStamp>2023-05-31T14:00:09-04:00</startTimeStamp>
				<endTimeStamp>2023-05-31T14:15:20-04:00</endTimeStamp>
				<author>
					<name>User</name>
				</author>
				<source>
					<applicationSoftware version="7.1">Data Collector</applicationSoftware>
					<instrumentControlSoftware version="8.2  20201204">EMPYREAN</instrumentControlSoftware>
					<instrumentID>0000000011260721</instrumentID>
				</source>
			</header>
			<dataPoints>
				<positions axis="2Theta" unit="deg">
					<startPosition>43.3653843891505</startPosition>
					<endPosition>46.712654160367</endPosition>
				</positions>
				<positions axis="Omega" unit="deg">
					<commonPosition>22.5209096373794</commonPosition>
				</positions>
				<positions axis="Phi" unit="deg">
					<commonPosition>0</commonPosition>
				</positions>
				<positions axis="Chi" unit="deg">
					<commonPosition>-0.72</commonPosition>
				</positions>
				<positions axis="Z" unit="mm">
					<commonPosition>8.487</commonPosition>
				</positions>
				<commonCountingTime unit="seconds">0.974</commonCountingTime>
				<counts unit="counts">0 0 0 0 0 0 0 1 0 1 2 0 1 0 1 0 0 0 1 1 0 0 1 0 0 2 0 0 1 1 1 0 0 1 1 1 0 1 0 1 1 0 0 0 0 1 0 1 1 1 0 0 0 1 0 0 0 0 1 0 0 0 0 0 1 1 1 0 0 0 0 1 0 1 0 0 0 1 0 1 0 0 0 0 0 0 1 0 0 0 0 0 1 0 0 0 0 0 1 0 1 0 0 0 2 1 0 0 0 0 1 0 1 1 0 0 0 1 0 1 0 0 2 0 1 0 0 0 1 0 1 1 0 1 2 2 0 1 0 1 0 0 0 0 0 2 0 0 0 1 0 0 0 1 0 0 0 1 1 0 0 0 0 0 1 1 0 1 1 0 1 1 0 0 0 0 1 0 0 0 0 0 1 0 0 0 0 1 0 1 0 3 1 0 0 2 1 0 1 1 2 1 2 2 0 0 2 0 1 0 3 0 2 1 1 0 2 1 1 0 1 0 0 2 2 0 3 1 1 2 2 2 6 3 5 4 1 6 3 4 4 4 1 1 1 1 2 0 0 1 0 1 0 0 1</counts>
			</dataPoints>
		</scan>
		<scan status="Completed" appendNumber="0" scanAxis="2Theta" mode="Continuous">
			<header>
				<startTimeStamp>2023-05-31T14:00:09-04:00</startTimeStamp>
				<endTimeStamp>2023-05-31T14:15:20-04:00</endTimeStamp>
				<author>
					<name>User</name>
				</author>
				<source>
					<applicationSoftware version="7.1">Data Collector</applicationSoftware>
					<instrumentControlSoftware version="8.2  20201204">EMPYREAN</instrumentControlSoftware>
					<instrumentID>0000000011260721</instrumentID>
				</source>
			</header>
			<dataPoints>
				<positions axis="2Theta" unit="deg">
					<startPosition>43.3686669598304</startPosition>
					<endPosition>46.7159367310468</endPosition>
				</positions>
				<positions axis="Omega" unit="deg">
					<commonPosition>22.5225509227193</commonPosition>
				</positions>
				<positions axis="Phi" unit="deg">
					<commonPosition>0</commonPosition>
				</positions>
				<positions axis="Chi" unit="deg">
					<commonPosition>-0.72</commonPosition>
				</positions>
				<positions axis="Z" unit="mm">
					<commonPosition>8.487</commonPosition>
				</positions>
				<commonCountingTime unit="seconds">0.974</commonCountingTime>
				<counts unit="counts">1 0 0 0 0 0 0 0 0 0 0 1 2 1 0 1 1 2 0 0 2 0 1 0 1 0 1 0 0 1 0 0 1 0 0 0 0 0 0 0 0 1 1 2 0 0 0 0 0 0 0 1 0 2 0 0 0 0 0 0 0 0 0 1 0 0 0 0 1 1 1 0 2 0 0 0 3 0 0 0 0 0 1 0 0 1 0 0 0 0 0 0 0 0 1 0 0 0 0 0 0 0 0 0 0 0 0 0 0 2 0 1 0 0 0 1 0 0 0 0 0 1 0 1 0 1 0 2 1 0 0 0 1 0 0 0 0 0 0 0 1 0 1 0 0 0 0 0 2 0 1 0 0 2 0 0 1 1 0 2 0 0 0 0 0 0 0 0 0 0 0 1 0 1 0 0 1 0 0 0 0 0 1 0 0 0 0 0 0 0 0 1 0 1 1 0 0 1 0 0 0 0 1 0 0 1 0 2 1 1 0 0 1 0 0 1 1 2 1 1 1 2 0 0 0 1 0 1 2 0 1 4 3 2 4 3 4 7 1 2 1 1 0 1 1 0 0 0 1 0 0 1 0 2 1</counts>
			</dataPoints>
		</scan>
		<scan status="Completed" appendNumber="0" scanAxis="2Theta" mode="Continuous">
			<header>
				<startTimeStamp>2023-05-31T14:00:09-04:00</startTimeStamp>
				<endTimeStamp>2023-05-31T14:15:20-04:00</endTimeStamp>
				<author>
					<name>User</name>
				</author>
				<source>
					<applicationSoftware version="7.1">Data Collector</applicationSoftware>
					<instrumentControlSoftware version="8.2  20201204">EMPYREAN</instrumentControlSoftware>
					<instrumentID>0000000011260721</instrumentID>
				</source>
			</header>
			<dataPoints>
				<positions axis="2Theta" unit="deg">
					<startPosition>43.3719495305102</startPosition>
					<endPosition>46.7192193017267</endPosition>
				</positions>
				<positions axis="Omega" unit="deg">
					<commonPosition>22.5241922080592</commonPosition>
				</positions>
				<positions axis="Phi" unit="deg">
					<commonPosition>0</commonPosition>
				</positions>
				<positions axis="Chi" unit="deg">
					<commonPosition>-0.72</commonPosition>
				</positions>
				<positions axis="Z" unit="mm">
					<commonPosition>8.487</commonPosition>
				</positions>
				<commonCountingTime unit="seconds">0.974</commonCountingTime>
				<counts unit="counts">0 1 0 0 0 0 1 1 0 0 0 1 0 0 2 1 0 1 0 2 0 0 1 0 0 0 0 1 0 1 0 0 0 0 0 0 0 1 0 0 1 0 0 0 0 0 0 0 0 1 0 0 0 0 0 2 0 1 0 0 0 0 0 0 1 0 0 0 1 2 0 0 0 0 0 0 1 0 1 0 0 0 0 0 1 1 0 0 0 0 0 0 0 0 0 0 0 0 1 0 0 0 0 0 0 0 1 1 0 1 0 0 0 1 0 0 1 1 1 0 0 0 0 0 0 0 0 0 1 0 0 1 0 0 1 0 0 0 0 1 1 0 0 1 0 1 0 0 0 0 0 0 1 1 1 1 0 1 0 0 0 0 1 0 0 0 0 0 1 1 0 1 0 0 2 0 0 1 0 1 1 0 0 0 0 2 0 0 0 2 1 1 0 0 0 0 0 1 0 0 1 0 0 0 2 0 0 1 1 0 0 3 1 0 1 1 1 3 0 0 0 0 0 1 0 1 1 1 2 3 2 0 4 0 1 1 6 4 4 6 1 2 3 0 1 1 2 0 1 0 1 1 0 1 1</counts>
			</dataPoints>
		</scan>
		<scan status="Completed" appendNumber="0" scanAxis="2Theta" mode="Continuous">
			<header>
				<startTimeStamp>2023-05-31T14:00:09-04:00</startTimeStamp>
				<endTimeStamp>2023-05-31T14:15:20-04:00</endTimeStamp>
				<author>
					<name>User</name>
				</author>
				<source>
					<applicationSoftware version="7.1">Data Collector</applicationSoftware>
					<instrumentControlSoftware version="8.2  20201204">EMPYREAN</instrumentControlSoftware>
					<instrumentID>0000000011260721</instrumentID>
				</source>
			</header>
			<dataPoints>
				<positions axis="2Theta" unit="deg">
					<startPosition>43.37523210119</startPosition>
					<endPosition>46.7225018724065</endPosition>
				</positions>
				<positions axis="Omega" unit="deg">
					<commonPosition>22.5258334933991</commonPosition>
				</positions>
				<positions axis="Phi" unit="deg">
					<commonPosition>0</commonPosition>
				</positions>
				<positions axis="Chi" unit="deg">
					<commonPosition>-0.72</commonPosition>
				</positions>
				<positions axis="Z" unit="mm">
					<commonPosition>8.487</commonPosition>
				</positions>
				<commonCountingTime unit="seconds">0.974</commonCountingTime>
				<counts unit="counts">0 0 0 0 0 2 1 1 0 0 1 2 0 0 0 0 2 0 1 0 0 0 0 0 1 1 0 1 0 0 1 1 0 0 0 0 0 1 0 0 0 0 0 0 0 0 1 0 0 1 0 1 0 1 1 0 1 0 0 0 0 1 0 1 0 0 0 1 1 0 0 0 0 0 0 0 1 0 1 2 0 0 0 0 0 0 1 1 0 1 0 1 0 0 0 0 0 0 0 1 0 0 0 0 1 1 0 0 0 1 1 1 1 0 0 0 0 0 0 2 0 0 0 0 0 0 1 2 1 0 0 0 0 0 0 0 0 1 1 1 0 0 1 0 0 0 0 0 0 0 0 0 2 0 0 0 1 0 3 1 0 1 0 0 1 0 1 1 0 1 0 1 1 0 0 0 0 0 0 1 0 0 2 4 0 1 0 0 0 1 1 1 0 0 0 0 0 0 1 0 2 1 0 0 0 3 0 1 0 1 0 1 1 0 1 1 0 0 2 1 0 2 1 1 1 0 0 0 0 0 2 4 2 2 3 4 3 6 3 2 1 1 0 1 2 0 2 1 1 1 0 0 1 0 1</counts>
			</dataPoints>
		</scan>
		<scan status="Completed" appendNumber="0" scanAxis="2Theta" mode="Continuous">
			<header>
				<startTimeStamp>2023-05-31T14:00:09-04:00</startTimeStamp>
				<endTimeStamp>2023-05-31T14:15:20-04:00</endTimeStamp>
				<author>
					<name>User</name>
				</author>
				<source>
					<applicationSoftware version="7.1">Data Collector</applicationSoftware>
					<instrumentControlSoftware version="8.2  20201204">EMPYREAN</instrumentControlSoftware>
					<instrumentID>0000000011260721</instrumentID>
				</source>
			</header>
			<dataPoints>
				<positions axis="2Theta" unit="deg">
					<startPosition>43.3785146718698</startPosition>
					<endPosition>46.7257844430863</endPosition>
				</positions>
				<positions axis="Omega" unit="deg">
					<commonPosition>22.527474778739</commonPosition>
				</positions>
				<positions axis="Phi" unit="deg">
					<commonPosition>0</commonPosition>
				</positions>
				<positions axis="Chi" unit="deg">
					<commonPosition>-0.72</commonPosition>
				</positions>
				<positions axis="Z" unit="mm">
					<commonPosition>8.487</commonPosition>
				</positions>
				<commonCountingTime unit="seconds">0.974</commonCountingTime>
				<counts unit="counts">1 0 0 0 0 1 1 0 1 0 0 0 0 0 0 1 0 0 0 0 1 1 1 0 1 0 0 0 0 0 0 0 0 1 0 0 0 0 0 0 0 0 0 0 0 0 1 0 0 1 1 0 0 1 0 0 0 0 1 0 0 0 1 1 0 1 0 0 0 0 0 1 1 0 0 0 0 2 1 0 0 0 0 2 0 0 0 1 0 0 0 0 0 2 0 1 0 2 1 1 0 1 0 0 0 0 0 0 0 1 1 0 1 0 0 1 0 0 0 0 0 1 0 0 0 1 0 2 3 1 1 0 0 1 1 0 0 0 1 0 0 0 1 0 0 0 1 1 0 2 0 0 0 0 2 1 0 0 0 0 2 2 0 0 0 0 0 2 3 1 0 0 0 0 1 1 0 0 0 1 0 1 0 1 0 0 0 1 1 0 0 0 0 1 1 0 1 0 0 2 2 0 0 0 3 1 3 0 0 2 1 0 0 0 1 0 1 2 0 0 0 1 0 1 0 0 0 1 3 0 1 1 4 2 1 3 4 5 1 4 1 0 2 1 3 0 1 0 1 1 1 0 0 1 1</counts>
			</dataPoints>
		</scan>
		<scan status="Completed" appendNumber="0" scanAxis="2Theta" mode="Continuous">
			<header>
				<startTimeStamp>2023-05-31T14:00:09-04:00</startTimeStamp>
				<endTimeStamp>2023-05-31T14:15:20-04:00</endTimeStamp>
				<author>
					<name>User</name>
				</author>
				<source>
					<applicationSoftware version="7.1">Data Collector</applicationSoftware>
					<instrumentControlSoftware version="8.2  20201204">EMPYREAN</instrumentControlSoftware>
					<instrumentID>0000000011260721</instrumentID>
				</source>
			</header>
			<dataPoints>
				<positions axis="2Theta" unit="deg">
					<startPosition>43.3817972425497</startPosition>
					<endPosition>46.7290670137661</endPosition>
				</positions>
				<positions axis="Omega" unit="deg">
					<commonPosition>22.5291160640789</commonPosition>
				</positions>
				<positions axis="Phi" unit="deg">
					<commonPosition>0</commonPosition>
				</positions>
				<positions axis="Chi" unit="deg">
					<commonPosition>-0.72</commonPosition>
				</positions>
				<positions axis="Z" unit="mm">
					<commonPosition>8.487</commonPosition>
				</positions>
				<commonCountingTime unit="seconds">0.974</commonCountingTime>
				<counts unit="counts">0 0 1 1 0 0 0 0 1 0 0 1 0 0 0 0 0 0 0 0 0 0 1 2 0 1 0 0 0 0 0 2 1 0 0 0 0 0 0 0 0 1 0 0 0 0 1 0 1 0 0 0 1 0 0 0 0 0 1 0 1 1 0 1 1 0 1 0 0 0 0 0 0 1 1 1 0 0 0 0 0 1 0 0 0 0 0 0 0 0 0 0 1 0 1 1 0 1 0 1 0 1 0 0 0 2 1 0 0 0 1 1 1 0 0 1 0 0 0 0 0 0 0 0 0 1 0 2 1 2 0 0 0 1 0 0 1 0 1 1 0 1 0 0 1 1 0 1 0 0 1 0 0 1 0 0 0 0 0 1 0 0 0 0 1 0 1 0 0 0 0 0 0 1 0 0 0 0 1 1 2 0 1 0 2 0 0 1 2 0 1 0 0 0 0 1 1 0 0 0 0 0 1 0 1 0 0 0 0 1 0 0 0 2 0 0 2 0 1 0 1 1 1 1 1 0 0 2 1 0 0 4 4 5 1 5 7 4 6 3 1 2 0 0 0 1 1 1 1 1 0 0 1 1 0</counts>
			</dataPoints>
		</scan>
		<scan status="Completed" appendNumber="0" scanAxis="2Theta" mode="Continuous">
			<header>
				<startTimeStamp>2023-05-31T14:00:09-04:00</startTimeStamp>
				<endTimeStamp>2023-05-31T14:15:20-04:00</endTimeStamp>
				<author>
					<name>User</name>
				</author>
				<source>
					<applicationSoftware version="7.1">Data Collector</applicationSoftware>
					<instrumentControlSoftware version="8.2  20201204">EMPYREAN</instrumentControlSoftware>
					<instrumentID>0000000011260721</instrumentID>
				</source>
			</header>
			<dataPoints>
				<positions axis="2Theta" unit="deg">
					<startPosition>43.3850798132295</startPosition>
					<endPosition>46.732349584446</endPosition>
				</positions>
				<positions axis="Omega" unit="deg">
					<commonPosition>22.5307573494189</commonPosition>
				</positions>
				<positions axis="Phi" unit="deg">
					<commonPosition>0</commonPosition>
				</positions>
				<positions axis="Chi" unit="deg">
					<commonPosition>-0.72</commonPosition>
				</positions>
				<positions axis="Z" unit="mm">
					<commonPosition>8.487</commonPosition>
				</positions>
				<commonCountingTime unit="seconds">0.974</commonCountingTime>
				<counts unit="counts">0 0 1 0 0 0 1 0 0 0 1 0 0 0 0 2 0 1 0 0 0 0 0 0 0 1 0 1 0 0 1 0 0 0 0 0 0 0 0 0 1 0 0 0 0 0 0 0 0 0 0 0 0 0 0 1 1 1 0 0 0 1 0 0 0 0 0 1 1 0 0 0 0 0 0 0 0 0 0 0 2 0 1 1 2 2 0 0 1 0 1 1 1 0 0 0 0 0 0 1 0 0 0 1 1 0 1 0 0 0 0 0 0 0 0 0 0 0 1 0 1 0 0 1 0 0 0 2 3 0 0 0 0 0 0 0 0 0 0 1 1 0 1 1 0 0 0 0 2 1 0 0 0 0 1 0 0 1 0 1 1 1 1 0 0 0 0 0 0 1 0 0 0 2 0 0 0 0 2 0 1 0 1 0 1 0 0 1 0 1 0 0 0 0 2 0 0 0 0 2 2 1 1 0 1 0 0 1 0 0 1 2 1 0 2 0 1 1 0 0 0 0 1 0 1 1 0 1 0 3 1 3 1 5 3 3 6 5 4 2 2 2 0 0 0 2 1 1 0 0 1 0 1 0 0</counts>
			</dataPoints>
		</scan>
		<scan status="Completed" appendNumber="0" scanAxis="2Theta" mode="Continuous">
			<header>
				<startTimeStamp>2023-05-31T14:00:09-04:00</startTimeStamp>
				<endTimeStamp>2023-05-31T14:15:20-04:00</endTimeStamp>
				<author>
					<name>User</name>
				</author>
				<source>
					<applicationSoftware version="7.1">Data Collector</applicationSoftware>
					<instrumentControlSoftware version="8.2  20201204">EMPYREAN</instrumentControlSoftware>
					<instrumentID>0000000011260721</instrumentID>
				</source>
			</header>
			<dataPoints>
				<positions axis="2Theta" unit="deg">
					<startPosition>43.3883623839093</startPosition>
					<endPosition>46.7356321551258</endPosition>
				</positions>
				<positions axis="Omega" unit="deg">
					<commonPosition>22.5323986347588</commonPosition>
				</positions>
				<positions axis="Phi" unit="deg">
					<commonPosition>0</commonPosition>
				</positions>
				<positions axis="Chi" unit="deg">
					<commonPosition>-0.72</commonPosition>
				</positions>
				<positions axis="Z" unit="mm">
					<commonPosition>8.487</commonPosition>
				</positions>
				<commonCountingTime unit="seconds">0.974</commonCountingTime>
				<counts unit="counts">0 0 1 0 0 0 2 0 0 0 2 0 0 1 1 1 0 0 0 0 0 0 0 0 0 1 1 0 1 1 0 1 0 2 0 0 1 0 0 0 2 1 1 0 0 0 0 0 1 0 1 1 0 0 1 0 0 0 0 0 0 1 0 0 0 0 0 0 0 0 0 0 0 0 1 0 0 0 0 0 0 0 1 0 0 0 0 0 1 0 1 0 0 1 0 0 0 0 0 1 2 0 1 0 0 0 0 0 0 2 1 0 0 0 1 1 1 0 0 0 0 0 0 3 2 3 1 0 0 0 0 0 0 0 1 2 0 0 0 1 0 0 0 0 1 0 1 0 1 0 0 0 0 0 1 0 0 1 0 0 1 0 0 0 0 0 0 0 0 1 0 0 0 0 0 0 3 0 0 0 0 0 1 1 2 0 1 1 0 1 0 0 1 0 0 0 0 0 0 2 1 0 1 0 0 0 2 0 0 0 1 0 0 1 0 0 0 1 0 2 0 1 2 2 0 1 2 1 1 0 2 1 2 3 2 6 2 1 5 2 1 1 3 1 1 1 0 1 1 2 0 2 0 0 1</counts>
			</dataPoints>
		</scan>
		<scan status="Completed" appendNumber="0" scanAxis="2Theta" mode="Continuous">
			<header>
				<startTimeStamp>2023-05-31T14:00:09-04:00</startTimeStamp>
				<endTimeStamp>2023-05-31T14:15:20-04:00</endTimeStamp>
				<author>
					<name>User</name>
				</author>
				<source>
					<applicationSoftware version="7.1">Data Collector</applicationSoftware>
					<instrumentControlSoftware version="8.2  20201204">EMPYREAN</instrumentControlSoftware>
					<instrumentID>0000000011260721</instrumentID>
				</source>
			</header>
			<dataPoints>
				<positions axis="2Theta" unit="deg">
					<startPosition>43.3916449545891</startPosition>
					<endPosition>46.7389147258056</endPosition>
				</positions>
				<positions axis="Omega" unit="deg">
					<commonPosition>22.5340399200987</commonPosition>
				</positions>
				<positions axis="Phi" unit="deg">
					<commonPosition>0</commonPosition>
				</positions>
				<positions axis="Chi" unit="deg">
					<commonPosition>-0.72</commonPosition>
				</positions>
				<positions axis="Z" unit="mm">
					<commonPosition>8.487</commonPosition>
				</positions>
				<commonCountingTime unit="seconds">0.974</commonCountingTime>
				<counts unit="counts">0 0 0 0 0 0 0 0 0 0 0 0 0 0 0 1 0 0 1 0 0 0 0 0 0 0 0 0 0 0 0 0 0 0 0 1 0 1 1 0 0 1 1 1 1 0 0 0 0 1 0 0 0 0 0 0 0 0 0 0 0 0 1 0 0 0 1 3 0 0 0 1 1 0 0 1 0 0 1 0 2 0 0 0 0 0 1 0 3 0 1 2 0 0 0 0 0 1 2 0 1 0 0 1 1 0 1 1 0 0 0 1 1 0 2 1 0 0 0 0 0 0 0 0 1 1 3 1 1 0 0 0 2 1 1 1 0 0 1 0 1 0 0 0 0 1 0 0 1 1 1 0 0 2 0 0 0 2 0 2 0 1 0 1 0 2 1 0 1 0 2 0 1 2 0 0 0 0 0 0 1 0 0 1 2 1 0 0 2 0 1 0 0 0 0 0 2 0 2 2 1 0 1 0 2 1 0 1 0 1 1 0 0 2 2 2 1 0 0 2 0 1 2 2 1 0 1 3 2 2 3 1 4 3 3 4 3 4 3 1 1 0 5 2 0 2 1 0 1 0 1 1 0 1 0</counts>
			</dataPoints>
		</scan>
		<scan status="Completed" appendNumber="0" scanAxis="2Theta" mode="Continuous">
			<header>
				<startTimeStamp>2023-05-31T14:00:09-04:00</startTimeStamp>
				<endTimeStamp>2023-05-31T14:15:20-04:00</endTimeStamp>
				<author>
					<name>User</name>
				</author>
				<source>
					<applicationSoftware version="7.1">Data Collector</applicationSoftware>
					<instrumentControlSoftware version="8.2  20201204">EMPYREAN</instrumentControlSoftware>
					<instrumentID>0000000011260721</instrumentID>
				</source>
			</header>
			<dataPoints>
				<positions axis="2Theta" unit="deg">
					<startPosition>43.394927525269</startPosition>
					<endPosition>46.7421972964854</endPosition>
				</positions>
				<positions axis="Omega" unit="deg">
					<commonPosition>22.5356812054386</commonPosition>
				</positions>
				<positions axis="Phi" unit="deg">
					<commonPosition>0</commonPosition>
				</positions>
				<positions axis="Chi" unit="deg">
					<commonPosition>-0.72</commonPosition>
				</positions>
				<positions axis="Z" unit="mm">
					<commonPosition>8.487</commonPosition>
				</positions>
				<commonCountingTime unit="seconds">0.974</commonCountingTime>
				<counts unit="counts">0 0 2 1 1 1 2 0 2 1 1 0 0 0 0 0 0 1 0 0 0 1 1 1 0 0 0 1 0 0 0 0 0 1 0 3 0 1 0 0 1 1 0 0 1 0 0 0 0 0 1 0 0 0 0 2 0 0 0 1 1 0 0 0 0 0 0 0 0 0 0 0 0 0 1 1 0 0 1 0 0 0 0 1 1 1 0 1 0 0 0 0 0 0 0 1 0 0 2 0 0 0 0 0 0 2 0 1 1 0 0 0 1 0 0 0 0 0 0 0 0 0 0 0 1 0 2 0 1 1 0 0 0 0 0 0 0 1 0 0 0 2 0 0 0 1 0 2 0 1 0 0 0 0 0 0 1 2 0 1 0 0 1 0 1 0 0 1 1 0 0 0 0 0 0 0 1 0 1 0 0 0 1 1 0 0 0 0 0 1 0 1 1 1 0 0 0 0 0 1 0 0 1 0 0 1 0 1 0 1 0 0 0 1 1 0 3 0 0 0 0 1 1 1 3 0 2 3 1 2 3 2 5 5 3 7 3 6 3 0 0 0 2 2 2 1 1 1 0 1 2 0 0 0 1</counts>
			</dataPoints>
		</scan>
		<scan status="Completed" appendNumber="0" scanAxis="2Theta" mode="Continuous">
			<header>
				<startTimeStamp>2023-05-31T14:00:09-04:00</startTimeStamp>
				<endTimeStamp>2023-05-31T14:15:20-04:00</endTimeStamp>
				<author>
					<name>User</name>
				</author>
				<source>
					<applicationSoftware version="7.1">Data Collector</applicationSoftware>
					<instrumentControlSoftware version="8.2  20201204">EMPYREAN</instrumentControlSoftware>
					<instrumentID>0000000011260721</instrumentID>
				</source>
			</header>
			<dataPoints>
				<positions axis="2Theta" unit="deg">
					<startPosition>43.3982100959488</startPosition>
					<endPosition>46.7454798671653</endPosition>
				</positions>
				<positions axis="Omega" unit="deg">
					<commonPosition>22.5373224907785</commonPosition>
				</positions>
				<positions axis="Phi" unit="deg">
					<commonPosition>0</commonPosition>
				</positions>
				<positions axis="Chi" unit="deg">
					<commonPosition>-0.72</commonPosition>
				</positions>
				<positions axis="Z" unit="mm">
					<commonPosition>8.487</commonPosition>
				</positions>
				<commonCountingTime unit="seconds">0.974</commonCountingTime>
				<counts unit="counts">0 1 0 0 0 1 1 0 1 0 1 0 1 0 0 1 0 0 0 0 0 0 0 0 0 0 1 1 0 0 2 0 1 1 0 0 0 1 0 0 0 0 1 1 0 1 0 1 0 0 0 0 0 0 0 1 0 0 0 1 1 0 0 1 1 0 0 0 0 0 0 2 1 0 0 0 1 1 0 0 1 1 1 0 0 0 0 0 0 2 2 0 1 0 0 0 1 0 1 0 0 0 0 0 0 0 2 0 0 0 0 0 2 0 0 0 0 0 0 0 0 0 0 0 0 1 0 2 2 1 2 0 0 0 1 0 0 1 1 0 0 0 0 0 1 1 0 0 0 1 0 0 0 0 0 1 0 0 0 2 0 0 1 2 0 1 1 0 0 0 0 0 0 1 0 0 0 1 0 0 0 0 0 1 0 1 3 0 0 1 0 2 0 0 0 1 3 0 1 0 0 0 0 0 0 2 0 0 1 3 1 0 3 2 0 1 1 0 3 0 2 0 2 2 0 2 1 2 1 1 2 1 6 2 2 4 9 2 4 1 3 1 0 1 1 0 1 0 0 1 0 1 1 1 0</counts>
			</dataPoints>
		</scan>
		<scan status="Completed" appendNumber="0" scanAxis="2Theta" mode="Continuous">
			<header>
				<startTimeStamp>2023-05-31T14:00:09-04:00</startTimeStamp>
				<endTimeStamp>2023-05-31T14:15:20-04:00</endTimeStamp>
				<author>
					<name>User</name>
				</author>
				<source>
					<applicationSoftware version="7.1">Data Collector</applicationSoftware>
					<instrumentControlSoftware version="8.2  20201204">EMPYREAN</instrumentControlSoftware>
					<instrumentID>0000000011260721</instrumentID>
				</source>
			</header>
			<dataPoints>
				<positions axis="2Theta" unit="deg">
					<startPosition>43.4014926666286</startPosition>
					<endPosition>46.7487624378451</endPosition>
				</positions>
				<positions axis="Omega" unit="deg">
					<commonPosition>22.5389637761184</commonPosition>
				</positions>
				<positions axis="Phi" unit="deg">
					<commonPosition>0</commonPosition>
				</positions>
				<positions axis="Chi" unit="deg">
					<commonPosition>-0.72</commonPosition>
				</positions>
				<positions axis="Z" unit="mm">
					<commonPosition>8.487</commonPosition>
				</positions>
				<commonCountingTime unit="seconds">0.974</commonCountingTime>
				<counts unit="counts">0 1 0 0 1 0 1 0 0 0 2 0 0 0 0 0 1 0 0 0 1 0 0 0 0 0 0 0 0 0 0 0 0 0 1 1 0 1 0 0 0 0 0 0 0 1 0 0 1 0 0 0 0 0 1 1 0 2 1 0 1 1 0 2 0 0 0 0 2 1 2 0 1 1 0 0 1 0 0 1 1 1 0 0 0 0 0 1 0 0 0 1 1 0 1 0 0 0 0 0 0 1 1 1 1 2 0 0 0 0 0 0 2 1 0 0 0 0 0 0 0 0 1 0 0 0 0 1 1 3 0 0 0 0 0 0 1 0 0 0 0 0 1 0 1 0 1 0 2 0 0 0 0 0 0 0 0 0 1 0 0 0 0 0 0 0 1 0 0 0 1 0 0 1 0 0 0 0 1 0 1 0 0 1 0 1 0 0 0 0 0 0 0 1 0 0 1 0 0 2 1 0 0 2 2 1 0 0 1 2 1 0 0 0 0 1 0 3 2 2 0 1 0 0 2 1 1 0 3 4 1 3 5 6 1 1 6 0 1 1 0 2 1 2 1 1 1 0 1 1 0 2 0 0 2</counts>
			</dataPoints>
		</scan>
		<scan status="Completed" appendNumber="0" scanAxis="2Theta" mode="Continuous">
			<header>
				<startTimeStamp>2023-05-31T14:00:09-04:00</startTimeStamp>
				<endTimeStamp>2023-05-31T14:15:20-04:00</endTimeStamp>
				<author>
					<name>User</name>
				</author>
				<source>
					<applicationSoftware version="7.1">Data Collector</applicationSoftware>
					<instrumentControlSoftware version="8.2  20201204">EMPYREAN</instrumentControlSoftware>
					<instrumentID>0000000011260721</instrumentID>
				</source>
			</header>
			<dataPoints>
				<positions axis="2Theta" unit="deg">
					<startPosition>43.4047752373084</startPosition>
					<endPosition>46.7520450085249</endPosition>
				</positions>
				<positions axis="Omega" unit="deg">
					<commonPosition>22.5406050614583</commonPosition>
				</positions>
				<positions axis="Phi" unit="deg">
					<commonPosition>0</commonPosition>
				</positions>
				<positions axis="Chi" unit="deg">
					<commonPosition>-0.72</commonPosition>
				</positions>
				<positions axis="Z" unit="mm">
					<commonPosition>8.487</commonPosition>
				</positions>
				<commonCountingTime unit="seconds">0.974</commonCountingTime>
				<counts unit="counts">0 0 0 0 0 0 1 0 0 0 0 0 2 0 0 0 1 1 1 0 1 0 1 1 0 0 0 0 2 0 1 2 1 1 0 0 1 0 0 0 1 2 0 0 0 0 0 0 0 0 0 1 0 0 0 0 0 0 0 1 1 1 0 0 1 0 0 0 0 0 0 0 0 0 0 1 0 0 1 0 0 0 0 0 1 0 0 0 0 0 0 0 0 1 0 1 0 0 1 0 0 1 0 0 0 1 1 1 0 0 0 0 0 0 0 0 0 0 1 1 0 1 0 0 0 1 0 1 1 1 0 0 0 0 1 0 0 0 0 1 0 1 0 1 1 0 1 1 0 0 0 0 0 0 0 1 0 1 0 0 0 1 0 1 4 0 0 1 1 0 1 0 2 0 2 0 0 1 1 0 1 2 0 1 0 2 2 2 2 0 0 0 1 0 1 1 2 0 0 1 0 1 0 1 1 1 0 0 0 0 1 2 1 0 2 0 0 0 1 0 0 0 0 0 0 0 0 0 0 0 3 3 2 0 2 4 4 1 1 1 1 0 3 0 1 1 0 0 1 2 0 0 1 1 1</counts>
			</dataPoints>
		</scan>
		<scan status="Completed" appendNumber="0" scanAxis="2Theta" mode="Continuous">
			<header>
				<startTimeStamp>2023-05-31T14:00:09-04:00</startTimeStamp>
				<endTimeStamp>2023-05-31T14:15:20-04:00</endTimeStamp>
				<author>
					<name>User</name>
				</author>
				<source>
					<applicationSoftware version="7.1">Data Collector</applicationSoftware>
					<instrumentControlSoftware version="8.2  20201204">EMPYREAN</instrumentControlSoftware>
					<instrumentID>0000000011260721</instrumentID>
				</source>
			</header>
			<dataPoints>
				<positions axis="2Theta" unit="deg">
					<startPosition>43.4080578079883</startPosition>
					<endPosition>46.7553275792047</endPosition>
				</positions>
				<positions axis="Omega" unit="deg">
					<commonPosition>22.5422463467982</commonPosition>
				</positions>
				<positions axis="Phi" unit="deg">
					<commonPosition>0</commonPosition>
				</positions>
				<positions axis="Chi" unit="deg">
					<commonPosition>-0.72</commonPosition>
				</positions>
				<positions axis="Z" unit="mm">
					<commonPosition>8.487</commonPosition>
				</positions>
				<commonCountingTime unit="seconds">0.974</commonCountingTime>
[...]
					<commonPosition>-0.72</commonPosition>
				</positions>
				<positions axis="Z" unit="mm">
					<commonPosition>8.487</commonPosition>
				</positions>
				<commonCountingTime unit="seconds">0.974</commonCountingTime>
				<counts unit="counts">0 1 1 0 1 1 0 0 3 5 2 1 0 3 1 3 4 8 2 0 2 0 0 1 0 0 1 1 0 0 1 0 0 0 0 0 2 2 0 0 0 0 1 1 0 3 0 0 2 0 0 1 0 2 2 1 1 0 0 1 0 1 0 0 0 0 0 0 0 0 1 0 0 0 0 0 0 1 1 1 0 0 0 4 2 0 0 0 2 0 0 2 0 1 0 0 0 1 0 0 0 0 0 0 0 0 0 0 0 2 0 1 0 1 0 0 1 0 0 1 0 0 1 0 0 0 2 1 0 1 0 1 0 0 0 0 1 2 0 0 0 0 1 0 0 0 0 1 0 1 0 0 1 1 0 1 1 0 0 0 0 1 0 0 0 0 0 0 1 0 0 0 0 0 0 0 1 0 0 1 0 1 0 0 0 0 0 0 0 2 0 0 1 0 0 0 0 3 0 0 1 0 0 0 0 0 0 0 1 1 0 0 0 0 0 0 0 1 0 0 1 0 1 0 0 0 0 0 0 0 0 0 1 0 0 1 0 0 0 0 0 0 1 1 0 0 0 1 0 0 0 0 0 0 0</counts>
			</dataPoints>
		</scan>
		<scan status="Completed" appendNumber="0" scanAxis="2Theta" mode="Continuous">
			<header>
				<startTimeStamp>2023-05-31T14:00:09-04:00</startTimeStamp>
				<endTimeStamp>2023-05-31T14:15:20-04:00</endTimeStamp>
				<author>
					<name>User</name>
				</author>
				<source>
					<applicationSoftware version="7.1">Data Collector</applicationSoftware>
					<instrumentControlSoftware version="8.2  20201204">EMPYREAN</instrumentControlSoftware>
					<instrumentID>0000000011260721</instrumentID>
				</source>
			</header>
			<dataPoints>
				<positions axis="2Theta" unit="deg">
					<startPosition>46.3032851475935</startPosition>
					<endPosition>49.65055491881</endPosition>
				</positions>
				<positions axis="Omega" unit="deg">
					<commonPosition>23.9898600166009</commonPosition>
				</positions>
				<positions axis="Phi" unit="deg">
					<commonPosition>0</commonPosition>
				</positions>
				<positions axis="Chi" unit="deg">
					<commonPosition>-0.72</commonPosition>
				</positions>
				<positions axis="Z" unit="mm">
					<commonPosition>8.487</commonPosition>
				</positions>
				<commonCountingTime unit="seconds">0.974</commonCountingTime>
				<counts unit="counts">1 0 2 1 3 2 3 1 2 6 2 2 4 5 6 4 9 2 4 0 0 0 0 1 1 1 0 0 1 0 1 0 0 0 1 2 2 1 0 3 0 0 1 1 1 0 1 0 0 0 0 2 0 1 2 0 0 1 1 2 0 0 0 0 0 1 0 1 0 0 1 0 1 0 0 0 0 2 0 0 0 1 0 2 0 1 0 1 0 0 1 1 2 0 1 0 0 0 0 0 1 0 0 0 2 0 0 0 0 0 0 0 0 0 1 0 1 0 1 0 0 2 0 0 0 0 2 1 2 0 2 2 1 0 0 0 0 0 0 0 0 1 0 0 1 0 0 0 0 0 0 0 0 1 0 0 2 1 0 2 0 0 0 0 0 0 1 0 0 0 0 0 0 1 0 0 1 0 0 0 1 0 0 0 0 0 0 0 0 0 0 1 0 0 1 0 0 0 1 0 0 0 0 0 0 0 0 0 0 0 0 0 0 0 0 2 0 1 0 0 0 0 0 0 0 0 0 0 1 0 0 0 0 0 0 0 0 0 0 0 0 0 0 0 0 0 0 0 0 0 0 0 1 0 1</counts>
			</dataPoints>
		</scan>
		<scan status="Completed" appendNumber="0" scanAxis="2Theta" mode="Continuous">
			<header>
				<startTimeStamp>2023-05-31T14:00:09-04:00</startTimeStamp>
				<endTimeStamp>2023-05-31T14:15:20-04:00</endTimeStamp>
				<author>
					<name>User</name>
				</author>
				<source>
					<applicationSoftware version="7.1">Data Collector</applicationSoftware>
					<instrumentControlSoftware version="8.2  20201204">EMPYREAN</instrumentControlSoftware>
					<instrumentID>0000000011260721</instrumentID>
				</source>
			</header>
			<dataPoints>
				<positions axis="2Theta" unit="deg">
					<startPosition>46.3065677182733</startPosition>
					<endPosition>49.6538374894898</endPosition>
				</positions>
				<positions axis="Omega" unit="deg">
					<commonPosition>23.9915013019408</commonPosition>
				</positions>
				<positions axis="Phi" unit="deg">
					<commonPosition>0</commonPosition>
				</positions>
				<positions axis="Chi" unit="deg">
					<commonPosition>-0.72</commonPosition>
				</positions>
				<positions axis="Z" unit="mm">
					<commonPosition>8.487</commonPosition>
				</positions>
				<commonCountingTime unit="seconds">0.974</commonCountingTime>
				<counts unit="counts">2 0 0 0 3 5 3 0 5 2 0 4 1 3 3 2 8 5 0 0 1 0 1 1 1 0 1 0 0 0 1 1 0 1 1 1 0 0 2 2 1 0 0 0 0 0 2 0 1 1 1 0 0 1 0 1 0 1 1 0 0 0 0 0 1 1 1 0 0 0 0 1 0 2 0 0 1 1 1 0 0 2 0 0 0 0 0 1 0 0 0 0 0 0 0 0 1 1 1 0 0 0 0 0 1 0 0 0 1 0 0 0 1 1 0 0 0 0 0 1 1 1 0 1 1 2 2 3 6 0 1 0 2 0 1 0 1 0 0 0 0 1 0 1 1 1 1 0 0 0 3 0 0 0 0 0 0 0 0 0 0 0 1 0 0 1 1 2 0 0 0 0 0 1 0 0 0 0 2 0 0 0 2 0 0 0 1 0 0 0 0 0 1 0 0 0 0 0 0 0 0 0 0 0 0 1 0 0 0 0 0 0 0 0 1 1 0 0 0 1 0 1 0 0 1 1 0 1 1 0 0 0 0 2 0 2 1 1 0 1 0 0 1 1 0 0 1 0 0 0 2 0 0 0 0</counts>
			</dataPoints>
		</scan>
		<scan status="Completed" appendNumber="0" scanAxis="2Theta" mode="Continuous">
			<header>
				<startTimeStamp>2023-05-31T14:00:09-04:00</startTimeStamp>
				<endTimeStamp>2023-05-31T14:15:20-04:00</endTimeStamp>
				<author>
					<name>User</name>
				</author>
				<source>
					<applicationSoftware version="7.1">Data Collector</applicationSoftware>
					<instrumentControlSoftware version="8.2  20201204">EMPYREAN</instrumentControlSoftware>
					<instrumentID>0000000011260721</instrumentID>
				</source>
			</header>
			<dataPoints>
				<positions axis="2Theta" unit="deg">
					<startPosition>46.3098502889532</startPosition>
					<endPosition>49.6571200601697</endPosition>
				</positions>
				<positions axis="Omega" unit="deg">
					<commonPosition>23.9931425872807</commonPosition>
				</positions>
				<positions axis="Phi" unit="deg">
					<commonPosition>0</commonPosition>
				</positions>
				<positions axis="Chi" unit="deg">
					<commonPosition>-0.72</commonPosition>
				</positions>
				<positions axis="Z" unit="mm">
					<commonPosition>8.487</commonPosition>
				</positions>
				<commonCountingTime unit="seconds">0.974</commonCountingTime>
				<counts unit="counts">3 0 1 1 2 1 0 0 0 2 3 4 5 4 5 5 1 1 3 1 2 2 3 0 3 0 2 1 0 1 0 0 1 0 0 2 0 0 1 0 1 0 2 0 1 0 1 1 0 1 1 0 0 3 0 0 0 1 0 0 1 0 0 0 0 1 1 0 0 0 1 0 1 0 0 0 0 0 0 0 0 0 0 0 0 0 1 0 1 1 0 0 2 0 0 1 0 0 0 0 1 1 0 0 0 2 1 0 2 0 0 0 0 0 1 0 0 0 0 1 0 0 0 0 1 0 1 1 3 0 1 0 0 1 0 0 0 1 0 0 0 0 0 1 0 2 0 1 0 0 1 0 3 0 0 0 0 0 0 0 0 1 0 1 2 0 0 1 0 0 0 1 0 0 1 2 0 0 0 0 0 1 1 0 0 0 0 0 0 0 0 0 0 0 0 1 1 0 0 0 0 0 0 2 1 0 0 0 1 0 1 0 0 1 0 0 0 0 1 0 0 0 0 0 0 1 0 0 0 0 0 0 1 0 1 0 0 1 0 1 1 0 0 0 0 0 0 0 0 1 1 1 1 0 0</counts>
			</dataPoints>
		</scan>
		<scan status="Completed" appendNumber="0" scanAxis="2Theta" mode="Continuous">
			<header>
				<startTimeStamp>2023-05-31T14:00:09-04:00</startTimeStamp>
				<endTimeStamp>2023-05-31T14:15:20-04:00</endTimeStamp>
				<author>
					<name>User</name>
				</author>
				<source>
					<applicationSoftware version="7.1">Data Collector</applicationSoftware>
					<instrumentControlSoftware version="8.2  20201204">EMPYREAN</instrumentControlSoftware>
					<instrumentID>0000000011260721</instrumentID>
				</source>
			</header>
			<dataPoints>
				<positions axis="2Theta" unit="deg">
					<startPosition>46.313132859633</startPosition>
					<endPosition>49.6604026308495</endPosition>
				</positions>
				<positions axis="Omega" unit="deg">
					<commonPosition>23.9947838726206</commonPosition>
				</positions>
				<positions axis="Phi" unit="deg">
					<commonPosition>0</commonPosition>
				</positions>
				<positions axis="Chi" unit="deg">
					<commonPosition>-0.72</commonPosition>
				</positions>
				<positions axis="Z" unit="mm">
					<commonPosition>8.487</commonPosition>
				</positions>
				<commonCountingTime unit="seconds">0.974</commonCountingTime>
				<counts unit="counts">0 0 0 0 1 1 0 0 2 1 2 2 3 7 7 2 2 2 1 1 0 0 3 1 2 0 0 1 0 0 1 0 1 4 0 1 1 1 0 0 0 2 2 0 0 0 1 2 0 2 0 1 1 0 0 0 0 0 0 0 0 0 1 0 2 1 2 0 0 0 0 0 0 0 0 0 0 0 0 0 1 1 0 0 1 0 0 1 0 0 0 1 0 0 0 0 0 0 0 1 0 0 0 1 0 0 2 0 0 0 0 0 0 0 0 0 1 0 0 2 0 1 1 1 1 0 0 1 0 0 1 2 0 0 0 0 0 0 0 0 1 0 1 1 0 1 0 0 0 1 1 0 0 0 0 0 1 0 0 0 1 1 0 1 1 0 0 0 1 0 0 0 1 0 1 0 0 0 0 0 0 1 2 0 1 0 0 0 0 1 0 0 0 0 1 0 0 0 1 1 0 1 0 1 0 0 0 0 0 0 0 0 0 0 0 0 0 0 0 0 0 0 0 0 0 1 0 0 0 1 0 0 1 0 0 1 0 0 0 0 0 0 0 0 0 1 0 1 0 0 1 1 0 0 0</counts>
			</dataPoints>
		</scan>
		<scan status="Completed" appendNumber="0" scanAxis="2Theta" mode="Continuous">
			<header>
				<startTimeStamp>2023-05-31T14:00:09-04:00</startTimeStamp>
				<endTimeStamp>2023-05-31T14:15:20-04:00</endTimeStamp>
				<author>
					<name>User</name>
				</author>
				<source>
					<applicationSoftware version="7.1">Data Collector</applicationSoftware>
					<instrumentControlSoftware version="8.2  20201204">EMPYREAN</instrumentControlSoftware>
					<instrumentID>0000000011260721</instrumentID>
				</source>
			</header>
			<dataPoints>
				<positions axis="2Theta" unit="deg">
					<startPosition>46.3164154303128</startPosition>
					<endPosition>49.6636852015293</endPosition>
				</positions>
				<positions axis="Omega" unit="deg">
					<commonPosition>23.9964251579605</commonPosition>
				</positions>
				<positions axis="Phi" unit="deg">
					<commonPosition>0</commonPosition>
				</positions>
				<positions axis="Chi" unit="deg">
					<commonPosition>-0.72</commonPosition>
				</positions>
				<positions axis="Z" unit="mm">
					<commonPosition>8.487</commonPosition>
				</positions>
				<commonCountingTime unit="seconds">0.974</commonCountingTime>
				<counts unit="counts">1 2 1 0 1 1 0 1 2 1 5 5 4 7 7 5 3 3 1 2 1 3 1 1 1 0 0 1 1 1 0 1 1 0 1 2 0 0 1 1 0 0 1 1 2 0 1 0 3 1 0 0 1 0 0 0 1 1 0 0 0 0 2 0 1 0 0 1 1 0 0 1 0 0 0 1 0 0 0 0 0 0 1 1 1 0 1 1 0 1 0 1 1 1 1 0 1 0 1 1 0 1 0 1 0 2 3 1 0 0 0 0 0 0 0 0 0 0 0 0 0 0 0 1 0 0 1 0 0 0 1 0 2 1 0 0 2 0 0 0 0 0 0 1 0 1 2 0 0 0 0 0 1 0 0 1 1 0 0 0 0 0 0 0 1 0 0 0 0 0 0 0 2 2 0 1 0 1 0 0 1 0 0 0 0 0 0 0 0 0 0 0 0 0 0 0 0 0 0 0 0 0 1 0 0 0 0 0 0 0 0 0 0 0 1 0 0 0 0 1 0 0 0 0 0 0 2 0 0 0 1 1 0 0 0 0 1 0 0 0 1 0 0 0 1 0 0 0 0 0 0 0 1 0 0</counts>
			</dataPoints>
		</scan>
		<scan status="Completed" appendNumber="0" scanAxis="2Theta" mode="Continuous">
			<header>
				<startTimeStamp>2023-05-31T14:00:09-04:00</startTimeStamp>
				<endTimeStamp>2023-05-31T14:15:20-04:00</endTimeStamp>
				<author>
					<name>User</name>
				</author>
				<source>
					<applicationSoftware version="7.1">Data Collector</applicationSoftware>
					<instrumentControlSoftware version="8.2  20201204">EMPYREAN</instrumentControlSoftware>
					<instrumentID>0000000011260721</instrumentID>
				</source>
			</header>
			<dataPoints>
				<positions axis="2Theta" unit="deg">
					<startPosition>46.3196980009926</startPosition>
					<endPosition>49.6669677722091</endPosition>
				</positions>
				<positions axis="Omega" unit="deg">
					<commonPosition>23.9980664433004</commonPosition>
				</positions>
				<positions axis="Phi" unit="deg">
					<commonPosition>0</commonPosition>
				</positions>
				<positions axis="Chi" unit="deg">
					<commonPosition>-0.72</commonPosition>
				</positions>
				<positions axis="Z" unit="mm">
					<commonPosition>8.487</commonPosition>
				</positions>
				<commonCountingTime unit="seconds">0.974</commonCountingTime>
				<counts unit="counts">0 2 0 0 0 1 1 1 1 0 0 5 3 4 8 4 5 4 5 2 1 1 0 1 0 0 1 1 0 1 0 3 0 0 0 2 1 1 1 1 1 0 0 0 1 0 3 0 0 0 2 0 0 0 2 1 1 0 0 0 1 0 0 1 1 0 1 0 0 0 0 1 0 0 1 1 0 1 0 0 0 1 0 2 0 0 0 1 0 0 0 0 1 1 1 1 0 2 1 0 0 1 0 0 0 0 0 1 1 1 0 0 0 0 0 0 1 0 0 0 0 0 1 0 0 1 1 2 3 0 0 0 0 0 1 0 0 0 0 0 0 0 1 0 0 0 0 0 0 0 0 0 0 0 0 0 0 0 0 0 1 0 1 0 0 1 0 1 0 0 0 2 0 1 1 0 0 0 1 0 0 1 1 0 1 0 0 0 0 2 0 0 0 0 0 0 0 0 0 0 0 0 0 0 0 0 1 1 0 0 0 0 0 0 1 1 0 0 0 0 0 0 1 0 1 0 0 1 1 0 0 0 2 0 1 0 0 0 0 1 1 0 0 0 0 0 0 0 0 0 1 0 1 0 0</counts>
			</dataPoints>
		</scan>
		<scan status="Completed" appendNumber="0" scanAxis="2Theta" mode="Continuous">
			<header>
				<startTimeStamp>2023-05-31T14:00:09-04:00</startTimeStamp>
				<endTimeStamp>2023-05-31T14:15:20-04:00</endTimeStamp>
				<author>
					<name>User</name>
				</author>
				<source>
					<applicationSoftware version="7.1">Data Collector</applicationSoftware>
					<instrumentControlSoftware version="8.2  20201204">EMPYREAN</instrumentControlSoftware>
					<instrumentID>0000000011260721</instrumentID>
				</source>
			</header>
			<dataPoints>
				<positions axis="2Theta" unit="deg">
					<startPosition>46.3229805716725</startPosition>
					<endPosition>49.670250342889</endPosition>
				</positions>
				<positions axis="Omega" unit="deg">
					<commonPosition>23.9997077286404</commonPosition>
				</positions>
				<positions axis="Phi" unit="deg">
					<commonPosition>0</commonPosition>
				</positions>
				<positions axis="Chi" unit="deg">
					<commonPosition>-0.72</commonPosition>
				</positions>
				<positions axis="Z" unit="mm">
					<commonPosition>8.487</commonPosition>
				</positions>
				<commonCountingTime unit="seconds">0.974</commonCountingTime>
				<counts unit="counts">0 0 5 1 0 4 2 1 1 7 5 2 8 7 5 9 3 0 0 1 1 1 0 1 0 0 1 0 1 0 1 1 1 1 0 0 2 1 2 1 2 2 0 2 1 2 0 0 0 2 1 1 0 0 0 1 1 2 0 3 0 2 0 0 2 2 0 0 0 0 0 0 0 1 0 0 0 0 0 0 0 0 0 0 1 0 0 0 0 0 1 0 0 0 0 0 1 1 0 0 0 0 0 0 0 0 0 0 0 0 0 0 1 1 1 0 0 0 0 1 0 0 0 1 0 0 0 0 1 0 0 0 1 0 0 1 2 0 0 1 2 1 1 1 0 0 1 1 0 0 0 0 0 1 0 0 0 0 0 0 0 1 0 1 0 0 0 0 0 2 0 0 0 0 0 0 0 0 0 1 0 0 0 0 1 1 0 0 1 0 1 0 1 0 1 0 1 1 0 0 0 0 0 0 0 0 0 0 1 0 1 0 0 0 0 0 2 0 1 0 0 0 0 0 1 0 0 0 0 1 0 1 0 0 0 0 3 0 0 0 1 0 0 0 0 0 0 0 0 0 0 0 0 0 0</counts>
			</dataPoints>
		</scan>
		<scan status="Completed" appendNumber="0" scanAxis="2Theta" mode="Continuous">
			<header>
				<startTimeStamp>2023-05-31T14:00:09-04:00</startTimeStamp>
				<endTimeStamp>2023-05-31T14:15:20-04:00</endTimeStamp>
				<author>
					<name>User</name>
				</author>
				<source>
					<applicationSoftware version="7.1">Data Collector</applicationSoftware>
					<instrumentControlSoftware version="8.2  20201204">EMPYREAN</instrumentControlSoftware>
					<instrumentID>0000000011260721</instrumentID>
				</source>
			</header>
			<dataPoints>
				<positions axis="2Theta" unit="deg">
					<startPosition>46.3262631423523</startPosition>
					<endPosition>49.6735329135688</endPosition>
				</positions>
				<positions axis="Omega" unit="deg">
					<commonPosition>24.0013490139803</commonPosition>
				</positions>
				<positions axis="Phi" unit="deg">
					<commonPosition>0</commonPosition>
				</positions>
				<positions axis="Chi" unit="deg">
					<commonPosition>-0.72</commonPosition>
				</positions>
				<positions axis="Z" unit="mm">
					<commonPosition>8.487</commonPosition>
				</positions>
				<commonCountingTime unit="seconds">0.974</commonCountingTime>
				<counts unit="counts">0 0 1 2 2 3 4 3 2 2 2 3 6 5 4 4 0 2 0 2 0 0 2 1 1 0 2 1 2 1 0 0 2 0 0 1 0 2 1 1 2 0 1 0 2 0 0 0 0 0 0 2 0 3 0 0 0 1 1 0 3 1 0 1 0 0 0 1 1 0 0 2 0 2 0 3 0 0 1 0 0 0 0 0 0 2 0 0 0 0 0 0 0 0 0 0 1 0 0 1 0 1 1 0 0 0 0 1 0 0 0 0 0 1 0 0 2 2 0 0 0 0 0 1 0 0 1 2 5 2 0 0 0 0 0 0 0 0 0 0 1 0 0 0 0 0 0 1 0 0 0 0 1 2 0 0 0 0 1 0 0 0 0 2 0 0 0 0 0 1 0 0 0 0 0 0 0 2 0 0 0 0 0 0 0 2 2 0 0 0 1 0 0 0 0 0 0 0 1 0 0 0 0 0 0 0 0 0 0 0 1 0 0 0 0 0 1 0 1 0 0 0 1 1 0 1 0 0 0 0 0 0 0 0 1 0 0 0 1 0 0 0 1 0 1 0 0 0 0 0 0 0 0 0 0</counts>
			</dataPoints>
		</scan>
		<scan status="Completed" appendNumber="0" scanAxis="2Theta" mode="Continuous">
			<header>
				<startTimeStamp>2023-05-31T14:00:09-04:00</startTimeStamp>
				<endTimeStamp>2023-05-31T14:15:20-04:00</endTimeStamp>
				<author>
					<name>User</name>
				</author>
				<source>
					<applicationSoftware version="7.1">Data Collector</applicationSoftware>
					<instrumentControlSoftware version="8.2  20201204">EMPYREAN</instrumentControlSoftware>
					<instrumentID>0000000011260721</instrumentID>
				</source>
			</header>
			<dataPoints>
				<positions axis="2Theta" unit="deg">
					<startPosition>46.3295457130321</startPosition>
					<endPosition>49.6768154842486</endPosition>
				</positions>
				<positions axis="Omega" unit="deg">
					<commonPosition>24.0029902993202</commonPosition>
				</positions>
				<positions axis="Phi" unit="deg">
					<commonPosition>0</commonPosition>
				</positions>
				<positions axis="Chi" unit="deg">
					<commonPosition>-0.72</commonPosition>
				</positions>
				<positions axis="Z" unit="mm">
					<commonPosition>8.487</commonPosition>
				</positions>
				<commonCountingTime unit="seconds">0.974</commonCountingTime>
				<counts unit="counts">1 0 1 1 2 0 1 2 4 3 4 2 7 7 8 5 3 1 3 1 1 1 1 0 1 1 0 0 0 0 0 0 1 1 1 0 3 1 1 1 1 1 3 1 1 1 3 3 0 0 0 2 0 0 0 0 2 0 1 0 1 0 0 1 0 0 0 0 0 1 1 0 1 0 1 0 0 1 0 1 1 0 1 1 0 1 1 0 0 0 0 0 0 0 0 1 1 1 0 0 0 0 0 1 0 1 2 1 0 0 1 0 1 1 0 0 0 0 0 0 0 1 0 2 1 5 0 1 0 2 1 1 0 1 0 0 0 0 0 0 0 0 1 0 0 0 0 0 0 0 0 0 0 0 1 0 0 0 0 0 0 0 0 0 0 0 0 0 0 0 1 0 0 0 0 0 1 0 0 1 0 1 1 0 0 0 0 0 0 0 0 0 0 0 0 0 0 1 0 0 0 0 0 0 0 1 0 0 0 1 0 1 0 0 1 0 1 0 0 0 1 0 0 0 1 1 0 0 1 0 0 1 0 0 0 1 0 0 1 0 0 0 0 0 0 0 0 0 0 1 0 0 0 1 1</counts>
			</dataPoints>
		</scan>
		<scan status="Completed" appendNumber="0" scanAxis="2Theta" mode="Continuous">
			<header>
				<startTimeStamp>2023-05-31T14:00:09-04:00</startTimeStamp>
				<endTimeStamp>2023-05-31T14:15:20-04:00</endTimeStamp>
				<author>
					<name>User</name>
				</author>
				<source>
					<applicationSoftware version="7.1">Data Collector</applicationSoftware>
					<instrumentControlSoftware version="8.2  20201204">EMPYREAN</instrumentControlSoftware>
					<instrumentID>0000000011260721</instrumentID>
				</source>
			</header>
			<dataPoints>
				<positions axis="2Theta" unit="deg">
					<startPosition>46.3328282837119</startPosition>
					<endPosition>49.6800980549284</endPosition>
				</positions>
				<positions axis="Omega" unit="deg">
					<commonPosition>24.0046315846601</commonPosition>
				</positions>
				<positions axis="Phi" unit="deg">
					<commonPosition>0</commonPosition>
				</positions>
				<positions axis="Chi" unit="deg">
					<commonPosition>-0.72</commonPosition>
				</positions>
				<positions axis="Z" unit="mm">
					<commonPosition>8.487</commonPosition>
				</positions>
				<commonCountingTime unit="seconds">0.974</commonCountingTime>
				<counts unit="counts">2 2 0 0 1 3 3 3 3 6 2 6 7 6 4 3 4 0 0 2 0 2 0 1 0 0 0 1 0 0 0 1 0 2 2 1 0 2 0 0 0 0 0 0 1 0 0 0 0 1 1 1 0 0 1 2 0 1 0 0 0 0 0 0 0 0 2 0 2 1 1 0 1 0 0 0 0 0 0 0 0 1 0 2 0 0 0 0 0 0 0 0 0 1 0 1 1 1 0 1 0 0 0 0 0 0 1 0 1 0 0 1 0 0 0 0 0 0 0 1 1 0 0 1 2 0 0 1 1 4 0 0 0 2 0 0 1 0 0 0 1 0 1 0 1 0 0 0 1 0 0 0 1 1 0 0 0 0 0 0 1 0 0 0 1 0 0 0 0 1 0 0 1 0 0 0 0 0 0 0 0 0 0 1 0 1 1 0 2 1 0 0 0 0 1 0 0 0 2 0 0 0 1 0 0 1 1 0 0 0 0 1 0 0 0 0 1 0 0 0 0 0 0 0 0 0 0 0 0 0 0 0 0 2 0 1 0 0 0 1 0 0 0 0 0 0 0 0 0 0 1 0 1 0 0</counts>
			</dataPoints>
		</scan>
		<scan status="Completed" appendNumber="0" scanAxis="2Theta" mode="Continuous">
			<header>
				<startTimeStamp>2023-05-31T14:00:09-04:00</startTimeStamp>
				<endTimeStamp>2023-05-31T14:15:20-04:00</endTimeStamp>
				<author>
					<name>User</name>
				</author>
				<source>
					<applicationSoftware version="7.1">Data Collector</applicationSoftware>
					<instrumentControlSoftware version="8.2  20201204">EMPYREAN</instrumentControlSoftware>
					<instrumentID>0000000011260721</instrumentID>
				</source>
			</header>
			<dataPoints>
				<positions axis="2Theta" unit="deg">
					<startPosition>46.3361108543918</startPosition>
					<endPosition>49.6833806256083</endPosition>
				</positions>
				<positions axis="Omega" unit="deg">
					<commonPosition>24.00627287</commonPosition>
				</positions>
				<positions axis="Phi" unit="deg">
					<commonPosition>0</commonPosition>
				</positions>
				<positions axis="Chi" unit="deg">
					<commonPosition>-0.72</commonPosition>
				</positions>
				<positions axis="Z" unit="mm">
					<commonPosition>8.487</commonPosition>
				</positions>
				<commonCountingTime unit="seconds">0.974</commonCountingTime>
				<counts unit="counts">2 1 2 0 1 2 3 1 0 1 1 4 6 9 0 2 3 4 0 3 2 0 0 0 0 3 0 0 4 1 0 0 1 0 1 2 0 1 2 1 0 2 1 1 0 0 0 1 2 0 0 0 0 1 0 0 0 0 0 0 0 0 0 1 1 0 0 0 2 0 0 0 0 1 0 1 0 0 0 0 0 0 0 0 1 0 0 0 1 0 0 1 0 0 3 0 1 0 2 0 1 0 1 0 0 0 1 0 1 0 0 0 1 0 1 0 1 0 0 0 1 0 0 1 0 0 0 2 3 1 1 1 0 1 0 1 0 0 1 0 0 0 0 0 0 0 1 1 0 0 0 0 0 1 0 0 0 0 0 0 0 0 0 1 0 0 2 0 1 0 0 1 1 0 0 0 0 0 0 0 0 0 0 0 1 0 0 0 0 0 0 0 0 1 1 0 0 0 1 1 2 0 0 0 0 1 1 0 0 0 0 0 0 0 0 0 1 0 0 0 0 2 1 0 0 0 1 0 0 0 1 0 0 0 1 0 1 0 0 0 0 0 0 0 0 0 0 1 0 2 0 2 0 0 0</counts>
			</dataPoints>
		</scan>
	</xrdMeasurement>
</xrdMeasurements>